{"active":1715201600976,"date":0,"event":"draft","input":" ","sender_id":"57ec71b6-a18b-44c0-a581-818804af3b11"}
{"date":"2024-05-04T20:23:08.735Z","editing":{},"event":"chat","history":[{"author_id":"57ec71b6-a18b-44c0-a581-818804af3b11","content":"<span class=\"user-mention\" account-id=openai-gpt-3.5-turbo >@GPT-3.5</span> Help me fix my code.\n\n<details><summary>Context</summary>\n\nI ran a cell in a Sage Worksheet.\n\nI received the following error:\n\n```sage\nError in lines 3-3\nTraceback (most recent call last):\n  File \"/cocalc/lib/python3.11/site-packages/smc_sagews/sage_server.py\", line 1244, in execute\n    exec(\n  File \"\", line 1, in <module>\n  File \"sage/structure/element.pyx\", line 489, in sage.structure.element.Element.__getattr__\n    return self.getattr_from_category(name)\n  File \"sage/structure/element.pyx\", line 502, in sage.structure.element.Element.getattr_from_category\n    return getattr_from_other_class(self, cls, name)\n  File \"sage/cpython/getattr.pyx\", line 362, in sage.cpython.getattr.getattr_from_other_class\n    raise AttributeError(dummy_error_message)\nAttributeError: 'sage.matrix.matrix_rational_dense.Matrix_rational_dense' object has no attribute 'eignvalues'\n\n```\n\nMy SageMath Worksheet contains:\n\n```sage\n\"\"\"\nAutovalores e Autovetores\n\n\"\"\"\n\n#Calculando autovalor e autovetores da matriz\n\nA = matrix(QQ,[[1,3,-3], [0,4,0],[-3,3,1]])\nx = A.eignvalues()\ny = A.eigenvectors_right()\nz = A.eigenvectors_left()\nw = A.eigenspaces_right()\nshow(x)\nshow(y)\nshow(z)\nshow(w)\n```\n\n</details>","date":"2024-05-04T20:23:08.735Z"}],"sender_id":"57ec71b6-a18b-44c0-a581-818804af3b11"}
{"date":"2024-05-04T20:23:08.751Z","editing":{},"event":"chat","generating":false,"history":[{"author_id":"openai-gpt-3.5-turbo","content":"The error message points out a typo in the attribute name `eignvalues`. It should be corrected to `eigenvalues`.\n\nUpdate the line `x = A.eignvalues()` to `x = A.eigenvalues()` in your SageMath code.","date":"2024-05-04T20:23:11.335Z"}],"reply_to":"2024-05-04T20:23:08.735Z","sender_id":"openai-gpt-3.5-turbo"}
{"date":"2024-05-04T20:28:16.736Z","editing":{},"event":"chat","history":[{"author_id":"57ec71b6-a18b-44c0-a581-818804af3b11","content":"<span class=\"user-mention\" account-id=openai-gpt-3.5-turbo >@GPT-3.5</span> Help me fix my code.\n\n<details><summary>Context</summary>\n\nI ran a cell in a Sage Worksheet.\n\nI received the following error:\n\n```sage\nError in lines 2-2\nTraceback (most recent call last):\n  File \"/cocalc/lib/python3.11/site-packages/smc_sagews/sage_server.py\", line 1244, in execute\n    exec(\n  File \"\", line 1, in <module>\n  File \"/ext/sage/10.3/src/sage/modules/vector_space_morphism.py\", line 708, in linear_transformation\n    raise ValueError(\"side must be 'left' or 'right', not {0}\".format(side))\nValueError: side must be 'left' or 'right', not rigth\n\n```\n\nMy SageMath Worksheet contains:\n\n```sage\n#Calculando autovalor e autovetores da transformação linear\n\nA = matrix(QQ,[[1,3,-3], [0,4,0],[-3,3,1]])\nT = linear_transformation(A,side='rigth')\nx = T.eigenvalues()\ny = T.eigenvectors()\n```\n\n</details>","date":"2024-05-04T20:28:16.736Z"}],"sender_id":"57ec71b6-a18b-44c0-a581-818804af3b11"}
{"date":"2024-05-04T20:28:16.743Z","editing":{},"event":"chat","generating":false,"history":[{"author_id":"openai-gpt-3.5-turbo","content":"The error is due to a typo in the code. Instead of `side='rigth'`, it should be `side='right'`. \n\nHere is the corrected code:\n\n```sage\n#Calculando autovalor e autovetores da transformação linear\n\nA = matrix(QQ,[[1,3,-3], [0,4,0],[-3,3,1]])\nT = linear_transformation(A, side='right')\nx = T.eigenvalues()\ny = T.eigenvectors()\n```","date":"2024-05-04T20:28:18.962Z"}],"reply_to":"2024-05-04T20:28:16.736Z","sender_id":"openai-gpt-3.5-turbo"}
{"date":"2024-05-08T19:41:35.093Z","editing":{},"event":"chat","history":[{"author_id":"57ec71b6-a18b-44c0-a581-818804af3b11","content":"<span class=\"user-mention\" account-id=openai-gpt-3.5-turbo >@GPT-3.5</span> Help me fix my code.\n\n<details><summary>Context</summary>\n\nI ran a cell in a Sage Worksheet.\n\nI received the following error:\n\n```sage\nError in lines 5-5\nTraceback (most recent call last):\n  File \"sage/structure/category_object.pyx\", line 855, in sage.structure.category_object.CategoryObject.getattr_from_category\n    return self._cached_methods[name]\nKeyError: '_PolynomialRing_singular_repr__singular'\n\nDuring handling of the above exception, another exception occurred:\n\nTraceback (most recent call last):\n  File \"/ext/sage/10.3/src/sage/rings/polynomial/polynomial_singular_interface.py\", line 335, in _singular_\n    R = self.__singular\n        ^^^^^^^^^^^^^^^\n  File \"sage/structure/category_object.pyx\", line 849, in sage.structure.category_object.CategoryObject.__getattr__\n    return self.getattr_from_category(name)\n  File \"sage/structure/category_object.pyx\", line 864, in sage.structure.category_object.CategoryObject.getattr_from_category\n    attr = getattr_from_other_class(self, cls, name)\n  File \"sage/cpython/getattr.pyx\", line 357, in sage.cpython.getattr.getattr_from_other_class\n    raise AttributeError(dummy_error_message)\nAttributeError: 'PolynomialRing_field_with_category' object has no attribute '_PolynomialRing_singular_repr__singular'\n\nDuring handling of the above exception, another exception occurred:\n\nTraceback (most recent call last):\n  File \"sage/rings/polynomial/polynomial_element.pyx\", line 5051, in sage.rings.polynomial.polynomial_element.Polynomial.factor\n    P._singular_().set_ring()\n  File \"/ext/sage/10.3/src/sage/rings/polynomial/polynomial_singular_interface.py\", line 349, in _singular_\n    return self._singular_init_(singular)\n           ^^^^^^^^^^^^^^^^^^^^^^^^^^^^^^\n  File \"/ext/sage/10.3/src/sage/rings/polynomial/polynomial_singular_interface.py\", line 366, in _singular_init_\n    raise TypeError(\"no conversion of this ring to a Singular ring defined\")\nTypeError: no conversion of this ring to a Singular ring defined\n\nDuring handling of the above exception, another exception occurred:\n\nTraceback (most recent call last):\n  File \"/cocalc/lib/python3.11/site-packages/smc_sagews/sage_server.py\", line 1244, in execute\n    exec(\n  File \"\", line 1, in <module>\n  File \"sage/rings/polynomial/polynomial_element.pyx\", line 5080, in sage.rings.polynomial.polynomial_element.Polynomial.factor\n    raise NotImplementedError\nNotImplementedError\n\n```\n\nMy SageMath Worksheet contains:\n\n```sage\n\"\"\"\nAutovalores e Autovetores\n\n\"\"\"\n#Polinômio Característicos\nx, y, z = var('x,y,z')\n\nA = matrix(2, 2, [1,pi,3,4])\nT = linear_transformation(A,side='right')\nPC = T.charpoly().factor()\n\nshow(PC)\n```\n\n</details>","date":"2024-05-08T19:41:35.093Z"}],"sender_id":"57ec71b6-a18b-44c0-a581-818804af3b11"}
{"date":"2024-05-08T19:41:35.100Z","editing":{},"event":"chat","generating":false,"history":[{"author_id":"openai-gpt-3.5-turbo","content":"The error you're encountering seems to be related to a conversion issue in the SageMath worksheet between the polynomial ring and the Singular ring. \n\nYou can try the following steps to potentially fix the code:\n\n1. Ensure that all necessary packages and libraries are correctly imported.\n2. Check if the versions of SageMath and Singular are compatible.\n3. Verify if there are any syntax errors in the code provided.\n4. If the issue persists, you may need to delve into the source code or seek help from the SageMath community for further assistance.\n\nRemember to keep your software and packages up to date to prevent compatibility issues.","date":"2024-05-08T19:41:38.555Z"}],"reply_to":"2024-05-08T19:41:35.093Z","sender_id":"openai-gpt-3.5-turbo"}
{"date":"2024-05-08T20:44:04.257Z","editing":{},"event":"chat","history":[{"author_id":"57ec71b6-a18b-44c0-a581-818804af3b11","content":"<span class=\"user-mention\" account-id=openai-gpt-3.5-turbo >@GPT-3.5</span> Help me fix my code.\n\n<details><summary>Context</summary>\n\nI ran a cell in a Sage Worksheet.\n\nI received the following error:\n\n```sage\nError in lines 3-3\nTraceback (most recent call last):\n  File \"/cocalc/lib/python3.11/site-packages/smc_sagews/sage_server.py\", line 1244, in execute\n    exec(\n  File \"\", line 1, in <module>\n  File \"/ext/sage/10.3/src/sage/modules/free_module_morphism.py\", line 508, in eigenvalues\n    raise TypeError(\"not an endomorphism\")\nTypeError: not an endomorphism\n\n```\n\nMy SageMath Worksheet contains:\n\n```sage\n#Calculando autovalor e autovetores da transformação linear\nA = matrix(QQ,[[1,3,-3], [3,4,6]])\nT = linear_transformation(A, side='right')\nx = T.eigenvalues()\ny = T.eigenvectors()\nprint('Respectivamente, os autovalores e autovetores:')\nshow(x)\nshow(y)\n```\n\n</details>","date":"2024-05-08T20:44:04.257Z"}],"sender_id":"57ec71b6-a18b-44c0-a581-818804af3b11"}
{"date":"2024-05-08T20:44:04.271Z","editing":{},"event":"chat","generating":false,"history":[{"author_id":"openai-gpt-3.5-turbo","content":"The error \"TypeError: not an endomorphism\" in your code might be due to the fact that the linear transformation you are working with is not an endomorphism, which means the domain and codomain are different.\n\nTo fix this, make sure that the linear transformation you define is an endomorphism. This can be achieved by setting the domain and codomain of the linear transformation to be the same. Here is how you can modify the code:\n\n```sage\n# Calculating the eigenvalues and eigenvectors of a linear transformation\nA = matrix(QQ,[[1,3,-3], [3,4,6]])\nV = VectorSpace(QQ, 3)\nT = linear_transformation(V, V, A)\nx = T.eigenvalues()\ny = T.eigenvectors()\nprint('Respectively, the eigenvalues and eigenvectors are:')\nshow(x)\nshow(y)\n``` \n\nThis modification ensures that the domain and codomain are the same, making it an endomorphism.","date":"2024-05-08T20:44:09.150Z"}],"reply_to":"2024-05-08T20:44:04.257Z","sender_id":"openai-gpt-3.5-turbo"}
{"date":"2024-05-08T20:52:46.445Z","editing":{},"event":"chat","history":[{"author_id":"57ec71b6-a18b-44c0-a581-818804af3b11","content":"<span class=\"user-mention\" account-id=openai-gpt-3.5-turbo >@GPT-3.5</span> Help me fix my code.\n\n<details><summary>Context</summary>\n\nI ran a cell in a Sage Worksheet.\n\nI received the following error:\n\n```sage\nError in lines 2-2\nTraceback (most recent call last):\n  File \"/cocalc/lib/python3.11/site-packages/smc_sagews/sage_server.py\", line 1244, in execute\n    exec(\n  File \"\", line 1, in <module>\n  File \"/ext/sage/10.3/src/sage/modules/vector_space_morphism.py\", line 708, in linear_transformation\n    raise ValueError(\"side must be 'left' or 'right', not {0}\".format(side))\nValueError: side must be 'left' or 'right', not rigth\n\n```\n\nMy SageMath Worksheet contains:\n\n```sage\n#Calculando autovalor e autovetores da transformação linear\nA = matrix(QQ, [[1, 3], [3, 4]])\nT = linear_transformation(A,side='rigth')\nx = T.eigenvalues()\ny = T.eigenvectors()\nprint('Respectivamente, os autovalores e autovetores:')\nshow(x)\nshow(y)\n```\n\n</details>","date":"2024-05-08T20:52:46.445Z"}],"sender_id":"57ec71b6-a18b-44c0-a581-818804af3b11"}
{"date":"2024-05-08T20:52:46.464Z","editing":{},"event":"chat","generating":false,"history":[{"author_id":"openai-gpt-3.5-turbo","content":"The error in your code is due to a typo. \nYou have written `side='rigth'` instead of `side='right'` when defining the linear transformation `T`.\nTo fix the code, change `side='rigth'` to `side='right'` as follows:\n\n```sage\nT = linear_transformation(A, side='right')\n```","date":"2024-05-08T20:52:49.050Z"}],"reply_to":"2024-05-08T20:52:46.445Z","sender_id":"openai-gpt-3.5-turbo"}
{"date":"2024-05-08T20:53:21.090Z","editing":{},"event":"chat","history":[{"author_id":"57ec71b6-a18b-44c0-a581-818804af3b11","content":"<span class=\"user-mention\" account-id=openai-gpt-3.5-turbo >@GPT-3.5</span> Help me fix my code.\n\n<details><summary>Context</summary>\n\nI ran a cell in a Sage Worksheet.\n\nI received the following error:\n\n```sage\nError in lines 4-4\nTraceback (most recent call last):\n  File \"/cocalc/lib/python3.11/site-packages/smc_sagews/sage_server.py\", line 1244, in execute\n    exec(\n  File \"\", line 1, in <module>\n  File \"/ext/sage/10.3/src/sage/modules/free_module_morphism.py\", line 560, in eigenvectors\n    seigenvec = self.matrix().eigenvectors_left(extend=extend)\n                ^^^^^^^^^^^^^^^^^^^^^^^^^^^^^^^^^^^^^^^^^^^^^^\n  File \"sage/matrix/matrix2.pyx\", line 6949, in sage.matrix.matrix2.Matrix.eigenvectors_left\n    eigenspaces = self.eigenspaces_left(format='galois', algebraic_multiplicity=True)\n  File \"sage/matrix/matrix2.pyx\", line 6436, in sage.matrix.matrix2.Matrix.eigenspaces_left\n    raise NotImplementedError(''.join(msg).format(self.base_ring()))\nNotImplementedError: eigenspaces cannot be computed reliably for inexact rings such as Real Field with 53 bits of precision,\nconsult numerical or symbolic matrix classes for other options\n\n```\n\nMy SageMath Worksheet contains:\n\n```sage\n#Calculando autovalor e autovetores da transformação linear\nA = matrix(RR, [[1, 3], [3, 4]])\nT = linear_transformation(A,side='right')\nx = T.eigenvalues()\ny = T.eigenvectors()\nprint('Respectivamente, os autovalores e autovetores:')\nshow(x)\nshow(y)\n```\n\n</details>","date":"2024-05-08T20:53:21.090Z"}],"sender_id":"57ec71b6-a18b-44c0-a581-818804af3b11"}
{"date":"2024-05-08T20:53:21.097Z","editing":{},"event":"chat","generating":false,"history":[{"author_id":"openai-gpt-3.5-turbo","content":"The error message indicates that eigenspaces cannot be computed reliably for inexact rings like Real Field with 53 bits of precision. \n\nTo fix the code, you can change the matrix definition to use a symbolic ring, such as QQbar, instead of RR. Here's the corrected code:\n\n```sage\n# Calculating eigenvalues and eigenvectors of a linear transformation\nA = matrix(QQbar, [[1, 3], [3, 4]])\nT = linear_transformation(A, side='right')\nx = T.eigenvalues()\ny = T.eigenvectors()\nprint('Respectively, the eigenvalues and eigenvectors:')\nshow(x)\nshow(y)\n```","date":"2024-05-08T20:53:24.257Z"}],"reply_to":"2024-05-08T20:53:21.090Z","sender_id":"openai-gpt-3.5-turbo"}