{"active":1714432950344,"date":0,"event":"draft","input":" ","sender_id":"57ec71b6-a18b-44c0-a581-818804af3b11"}
{"date":"2024-04-29T23:07:23.735Z","editing":{},"event":"chat","history":[{"author_id":"57ec71b6-a18b-44c0-a581-818804af3b11","content":"<span class=\"user-mention\" account-id=openai-gpt-3.5-turbo >@GPT-3.5</span> Help me fix my code.\n\n<details><summary>Context</summary>\n\nI ran a cell in a Sage Worksheet.\n\nI received the following error:\n\n```sage\nError in lines 6-11\nTraceback (most recent call last):\n  File \"/cocalc/lib/python3.11/site-packages/smc_sagews/sage_server.py\", line 1245, in execute\n    compile(block + '\\n',\n  File \"<string>\", line 1\n    if bijetora is:\n                  ^\nSyntaxError: invalid syntax\n\n```\n\nMy SageMath Worksheet contains:\n\n```sage\n#Descobrindo se uma transformação linear é bijetora\nS(x,y,z,w)= [2*x-z+2*w,2*x-3*y+4*z]\nT = linear_transformation(SR^4,SR^2,S)\nbijetora = T.is_bijective()\ninjetora = T.is_injective()\nsobrejetora = T.is_surjective()\n\nif bijetora is:\n    print(\"A transformação %n\", T, \"é bijetora\")\nelse:\n    print(\"A transformação %n\", T, \"não é bijetora\")\n    show(injetora)\n    show(sobrejetora)\n```\n\n</details>","date":"2024-04-29T23:07:23.735Z"}],"sender_id":"57ec71b6-a18b-44c0-a581-818804af3b11"}
{"date":"2024-04-29T23:07:23.750Z","editing":{},"event":"chat","generating":false,"history":[{"author_id":"openai-gpt-3.5-turbo","content":"The issue in your code seems to be with the syntax of the `if` statement.\n\nChange `if bijetora is:` to `if bijetora:` in your code to fix the syntax error. This adjustment should resolve the error you encountered.","date":"2024-04-29T23:07:26.404Z"}],"reply_to":"2024-04-29T23:07:23.735Z","sender_id":"openai-gpt-3.5-turbo"}
{"date":"2024-04-29T23:16:04.498Z","editing":{},"event":"chat","history":[{"author_id":"57ec71b6-a18b-44c0-a581-818804af3b11","content":"<span class=\"user-mention\" account-id=openai-gpt-3.5-turbo >@GPT-3.5</span> Help me fix my code.\n\n<details><summary>Context</summary>\n\nI ran a cell in a Sage Worksheet.\n\nI received the following error:\n\n```sage\nError in lines 6-6\nTraceback (most recent call last):\n  File \"/cocalc/lib/python3.11/site-packages/smc_sagews/sage_server.py\", line 1244, in execute\n    exec(\n  File \"\", line 1, in <module>\n  File \"/ext/sage/10.3/src/sage/modules/matrix_morphism.py\", line 445, in inverse\n    return ~self\n           ^^^^^\n  File \"/ext/sage/10.3/src/sage/modules/matrix_morphism.py\", line 265, in __invert__\n    B = ~(self.matrix())\n        ^^^^^^^^^^^^^^^^\n  File \"sage/matrix/matrix0.pyx\", line 5731, in sage.matrix.matrix0.Matrix.__invert__\n    raise ArithmeticError(\"self must be a square matrix\")\nArithmeticError: self must be a square matrix\n\n```\n\nMy SageMath Worksheet contains:\n\n```sage\n#Verificando se uma transformação é isomorfismo e calculando a inversa\nS(x,y,z,w)= [2*x-z+2*w,2*x-3*y+4*z]; #Modificar aqui a transformação\nT = linear_transformation(SR^4,SR^2,S); #Modificar SR^\"\" \nbijetora = T.is_bijective()\ninjetora = T.is_injective()\nsobrejetora = T.is_surjective()\ninverso= T.inverse()([x,y,z,w])\n\nif bijetora or (T*inverso):\n    print(T,\"é um isomorfismo\")\n    show(T*inverso)\nelse:\n    print(T \"não é um isomorfismo\")\n    show(injetora)\n    show(sobrejetora)\n```\n\n</details>","date":"2024-04-29T23:16:04.498Z"}],"sender_id":"57ec71b6-a18b-44c0-a581-818804af3b11"}
{"date":"2024-04-29T23:16:04.519Z","editing":{},"event":"chat","generating":false,"history":[{"author_id":"openai-gpt-3.5-turbo","content":"The error \"ArithmeticError: self must be a square matrix\" is likely due to trying to invert a non-square matrix. Make sure that the input matrix to the linear transformation is a square matrix when defining the function `S(x,y,z,w)`.","date":"2024-04-29T23:16:06.311Z"}],"reply_to":"2024-04-29T23:16:04.498Z","sender_id":"openai-gpt-3.5-turbo"}
{"date":"2024-04-29T23:17:50.528Z","editing":{},"event":"chat","history":[{"author_id":"57ec71b6-a18b-44c0-a581-818804af3b11","content":"<span class=\"user-mention\" account-id=openai-gpt-3.5-turbo >@GPT-3.5</span> Help me fix my code.\n\n<details><summary>Context</summary>\n\nI ran a cell in a Sage Worksheet.\n\nI received the following error:\n\n```sage\nError in lines 2-2\nTraceback (most recent call last):\n  File \"/cocalc/lib/python3.11/site-packages/smc_sagews/sage_server.py\", line 1244, in execute\n    exec(\n  File \"\", line 1, in <module>\n  File \"/ext/sage/10.3/src/sage/modules/vector_space_morphism.py\", line 756, in linear_transformation\n    raise ValueError('symbolic function has the wrong number of inputs for domain')\nValueError: symbolic function has the wrong number of inputs for domain\n\n```\n\nMy SageMath Worksheet contains:\n\n```sage\n#Verificando se uma transformação é isomorfismo e calculando a inversa\nS(x,y,z)= [2*x-z,2*x-3*y+4*z,3*y+z]; #Modificar aqui a transformação\nT = linear_transformation(SR^4,SR^2,S); #Modificar SR^\"\" \nbijetora = T.is_bijective()\ninjetora = T.is_injective()\nsobrejetora = T.is_surjective()\ninverso= T.inverse()([x,y,z,w])\n\nif bijetora or (T*inverso):\n    print(T,\"é um isomorfismo\")\n    show(T*inverso)\nelse:\n    print(T \"não é um isomorfismo\")\n    show(injetora)\n    show(sobrejetora)\n```\n\n</details>","date":"2024-04-29T23:17:50.528Z"}],"sender_id":"57ec71b6-a18b-44c0-a581-818804af3b11"}
{"date":"2024-04-29T23:17:50.549Z","editing":{},"event":"chat","generating":false,"history":[{"author_id":"openai-gpt-3.5-turbo","content":"The error message \"symbolic function has the wrong number of inputs for domain\" indicates that the defined linear transformation is expecting a different number of inputs than what is provided in the domain.\n\nIn your SageMath code, you defined the linear transformation \\(S(x,y,z) = [2x-z, 2x-3y+4z, 3y+z]\\). However, when you create the linear transformation using `linear_transformation(SR^4,SR^2,S)`, you are specifying that it should operate from a 4-dimensional space to a 2-dimensional space. This mismatch in dimensions is likely causing the error.\n\nTo fix this, make sure that the number of inputs in your linear transformation function matches the dimension of the domain space.","date":"2024-04-29T23:17:53.539Z"}],"reply_to":"2024-04-29T23:17:50.528Z","sender_id":"openai-gpt-3.5-turbo"}
{"date":"2024-04-29T23:18:34.380Z","editing":{},"event":"chat","history":[{"author_id":"57ec71b6-a18b-44c0-a581-818804af3b11","content":"<span class=\"user-mention\" account-id=openai-gpt-3.5-turbo >@GPT-3.5</span> Help me fix my code.\n\n<details><summary>Context</summary>\n\nI ran a cell in a Sage Worksheet.\n\nI received the following error:\n\n```sage\nError in lines 6-6\nTraceback (most recent call last):\n  File \"sage/categories/map.pyx\", line 810, in sage.categories.map.Map.__call__\n    x = D(x)\n  File \"sage/structure/parent.pyx\", line 901, in sage.structure.parent.Parent.__call__\n    return mor._call_(x)\n  File \"sage/structure/coerce_maps.pyx\", line 163, in sage.structure.coerce_maps.DefaultConvertMap_unique._call_\n    raise\n  File \"sage/structure/coerce_maps.pyx\", line 158, in sage.structure.coerce_maps.DefaultConvertMap_unique._call_\n    return C._element_constructor(x)\n  File \"/ext/sage/10.3/src/sage/modules/free_module.py\", line 6401, in _element_constructor_\n    return FreeModule_generic_field._element_constructor_(self, e, *args, **kwds)\n           ^^^^^^^^^^^^^^^^^^^^^^^^^^^^^^^^^^^^^^^^^^^^^^^^^^^^^^^^^^^^^^^^^^^^^^\n  File \"/ext/sage/10.3/src/sage/modules/free_module.py\", line 2193, in _element_constructor_\n    return self.element_class(self, x, coerce, copy)\n           ^^^^^^^^^^^^^^^^^^^^^^^^^^^^^^^^^^^^^^^^^\n  File \"sage/modules/free_module_element.pyx\", line 4363, in sage.modules.free_module_element.FreeModuleElement_generic_dense.__init__\n    raise TypeError(\"entries must be a list of length %s\" % self.degree())\nTypeError: entries must be a list of length 3\n\nDuring handling of the above exception, another exception occurred:\n\nTraceback (most recent call last):\n  File \"/cocalc/lib/python3.11/site-packages/smc_sagews/sage_server.py\", line 1244, in execute\n    exec(\n  File \"\", line 1, in <module>\n  File \"sage/categories/map.pyx\", line 812, in sage.categories.map.Map.__call__\n    raise TypeError(\"%s fails to convert into the map's domain %s, but a `pushforward` method is not properly implemented\" % (x, D))\nTypeError: [x, y, z, w] fails to convert into the map's domain Vector space of dimension 3 over Symbolic Ring, but a `pushforward` method is not properly implemented\n\n```\n\nMy SageMath Worksheet contains:\n\n```sage\n#Verificando se uma transformação é isomorfismo e calculando a inversa\nS(x,y,z)= [2*x-z,2*x-3*y+4*z,3*y+z]; #Modificar aqui a transformação\nT = linear_transformation(SR^3,SR^3,S); #Modificar SR^\"\" \nbijetora = T.is_bijective()\ninjetora = T.is_injective()\nsobrejetora = T.is_surjective()\ninverso= T.inverse()([x,y,z,w])\n\nif bijetora or (T*inverso):\n    print(T,\"é um isomorfismo\")\n    show(T*inverso)\nelse:\n    print(T \"não é um isomorfismo\")\n    show(injetora)\n    show(sobrejetora)\n```\n\n</details>","date":"2024-04-29T23:18:34.380Z"}],"sender_id":"57ec71b6-a18b-44c0-a581-818804af3b11"}
{"date":"2024-04-29T23:18:34.409Z","editing":{},"event":"chat","generating":false,"history":[{"author_id":"openai-gpt-3.5-turbo","content":"The error message indicates that the length of the input list `[x, y, z, w]` does not match the expected length of 3 in the linear transformation function.\n\nYou need to ensure that the input list has a length of 3 when calling the `linear_transformation` function in your code snippet. The input should be in the form `[x, y, z]` rather than `[x, y, z, w]`. Fix this issue in your code by providing the correct input list with a length of 3.","date":"2024-04-29T23:18:37.073Z"}],"reply_to":"2024-04-29T23:18:34.380Z","sender_id":"openai-gpt-3.5-turbo"}
{"date":"2024-04-29T23:19:03.984Z","editing":{},"event":"chat","history":[{"author_id":"57ec71b6-a18b-44c0-a581-818804af3b11","content":"<span class=\"user-mention\" account-id=openai-gpt-3.5-turbo >@GPT-3.5</span> Help me fix my code.\n\n<details><summary>Context</summary>\n\nI ran a cell in a Sage Worksheet.\n\nI received the following error:\n\n```sage\nError in lines 7-13\nTraceback (most recent call last):\n  File \"/cocalc/lib/python3.11/site-packages/smc_sagews/sage_server.py\", line 1245, in execute\n    compile(block + '\\n',\n  File \"<string>\", line 5\n    print(T \"não é um isomorfismo\")\n            ^^^^^^^^^^^^^^^^^^^^^^\nSyntaxError: invalid syntax\n\n```\n\nMy SageMath Worksheet contains:\n\n```sage\n#Verificando se uma transformação é isomorfismo e calculando a inversa\nS(x,y,z)= [2*x-z,2*x-3*y+4*z,3*y+z]; #Modificar aqui a transformação\nT = linear_transformation(SR^3,SR^3,S); #Modificar SR^\"\" \nbijetora = T.is_bijective()\ninjetora = T.is_injective()\nsobrejetora = T.is_surjective()\ninverso= T.inverse()([x,y,z])\n\nif bijetora or (T*inverso):\n    print(T,\"é um isomorfismo\")\n    show(T*inverso)\nelse:\n    print(T \"não é um isomorfismo\")\n    show(injetora)\n    show(sobrejetora)\n```\n\n</details>","date":"2024-04-29T23:19:03.984Z"}],"sender_id":"57ec71b6-a18b-44c0-a581-818804af3b11"}
{"date":"2024-04-29T23:19:04.002Z","editing":{},"event":"chat","generating":false,"history":[{"author_id":"openai-gpt-3.5-turbo","content":"It looks like you are missing a comma after `print(T)` in your code snippet. Update the line to `print(T, \"não é um isomorfismo\")` and try running the cell again.","date":"2024-04-29T23:19:05.601Z"}],"reply_to":"2024-04-29T23:19:03.984Z","sender_id":"openai-gpt-3.5-turbo"}
{"date":"2024-04-29T23:19:39.362Z","editing":{},"event":"chat","history":[{"author_id":"57ec71b6-a18b-44c0-a581-818804af3b11","content":"<span class=\"user-mention\" account-id=openai-gpt-3.5-turbo >@GPT-3.5</span> Help me fix my code.\n\n<details><summary>Context</summary>\n\nI ran a cell in a Sage Worksheet.\n\nI received the following error:\n\n```sage\nError in lines 7-13\nTraceback (most recent call last):\n  File \"/cocalc/lib/python3.11/site-packages/smc_sagews/sage_server.py\", line 1244, in execute\n    exec(\n  File \"\", line 3, in <module>\n  File \"/ext/sage/10.3/src/sage/modules/matrix_morphism.py\", line 621, in __mul__\n    return self.parent()(self.matrix() * R(right))\n                                         ^^^^^^^^\n  File \"sage/structure/parent.pyx\", line 901, in sage.structure.parent.Parent.__call__\n    return mor._call_(x)\n  File \"sage/structure/coerce_maps.pyx\", line 163, in sage.structure.coerce_maps.DefaultConvertMap_unique._call_\n    raise\n  File \"sage/structure/coerce_maps.pyx\", line 158, in sage.structure.coerce_maps.DefaultConvertMap_unique._call_\n    return C._element_constructor(x)\n  File \"sage/symbolic/ring.pyx\", line 376, in sage.symbolic.ring.SymbolicRing._element_constructor_\n    return new_Expression(self, x)\n  File \"sage/symbolic/expression.pyx\", line 13817, in sage.symbolic.expression.new_Expression\n    raise TypeError(f\"unable to convert {x!r} to a symbolic expression\")\nTypeError: unable to convert (5/12*x + 1/12*y + 1/12*z, 1/18*x - 1/18*y + 5/18*z, -1/6*x + 1/6*y + 1/6*z) to a symbolic expression\n\n```\n\nMy SageMath Worksheet contains:\n\n```sage\n#Verificando se uma transformação é isomorfismo e calculando a inversa\nS(x,y,z)= [2*x-z,2*x-3*y+4*z,3*y+z]; #Modificar aqui a transformação\nT = linear_transformation(SR^3,SR^3,S); #Modificar SR^\"\" \nbijetora = T.is_bijective()\ninjetora = T.is_injective()\nsobrejetora = T.is_surjective()\ninverso= T.inverse()([x,y,z])\n\nif bijetora or (T*inverso):\n    print(T,\"é um isomorfismo\")\n    show(T*inverso)\nelse:\n    print(T, \"não é um isomorfismo\")\n    show(injetora)\n    show(sobrejetora)\n```\n\n</details>","date":"2024-04-29T23:19:39.362Z"}],"sender_id":"57ec71b6-a18b-44c0-a581-818804af3b11"}
{"date":"2024-04-29T23:19:39.376Z","editing":{},"event":"chat","generating":false,"history":[{"author_id":"openai-gpt-3.5-turbo","content":"The error occurs because the code is trying to convert a list of expressions into a symbolic expression, which is not possible. To fix this, modify the line where you define S(x,y,z) to explicitly create the vector using the vector constructor. \n\nReplace:\n\n```sage\nS(x,y,z)= [2*x-z,2*x-3*y+4*z,3*y+z]; #Modificar aqui a transformação\n```\n\nwith:\n\n```sage\nS(x,y,z) = vector([2*x-z, 2*x-3*y+4*z, 3*y+z]); #Modificar aqui a transformação\n```  ","date":"2024-04-29T23:19:41.919Z"}],"reply_to":"2024-04-29T23:19:39.362Z","sender_id":"openai-gpt-3.5-turbo"}
{"date":"2024-04-29T23:20:13.077Z","editing":{},"event":"chat","history":[{"author_id":"57ec71b6-a18b-44c0-a581-818804af3b11","content":"<span class=\"user-mention\" account-id=openai-gpt-3.5-turbo >@GPT-3.5</span> Help me fix my code.\n\n<details><summary>Context</summary>\n\nI ran a cell in a Sage Worksheet.\n\nI received the following error:\n\n```sage\nError in lines 7-13\nTraceback (most recent call last):\n  File \"/cocalc/lib/python3.11/site-packages/smc_sagews/sage_server.py\", line 1244, in execute\n    exec(\n  File \"\", line 3, in <module>\n  File \"/ext/sage/10.3/src/sage/modules/matrix_morphism.py\", line 621, in __mul__\n    return self.parent()(self.matrix() * R(right))\n                                         ^^^^^^^^\n  File \"sage/structure/parent.pyx\", line 901, in sage.structure.parent.Parent.__call__\n    return mor._call_(x)\n  File \"sage/structure/coerce_maps.pyx\", line 163, in sage.structure.coerce_maps.DefaultConvertMap_unique._call_\n    raise\n  File \"sage/structure/coerce_maps.pyx\", line 158, in sage.structure.coerce_maps.DefaultConvertMap_unique._call_\n    return C._element_constructor(x)\n  File \"sage/symbolic/ring.pyx\", line 376, in sage.symbolic.ring.SymbolicRing._element_constructor_\n    return new_Expression(self, x)\n  File \"sage/symbolic/expression.pyx\", line 13817, in sage.symbolic.expression.new_Expression\n    raise TypeError(f\"unable to convert {x!r} to a symbolic expression\")\nTypeError: unable to convert (5/12*x + 1/12*y + 1/12*z, 1/18*x - 1/18*y + 5/18*z, -1/6*x + 1/6*y + 1/6*z) to a symbolic expression\n\n```\n\nMy SageMath Worksheet contains:\n\n```sage\n#Verificando se uma transformação é isomorfismo e calculando a inversa\nS(x,y,z) = vector([2*x-z, 2*x-3*y+4*z, 3*y+z]); #Modificar aqui a transformação \nT = linear_transformation(SR^3,SR^3,S); #Modificar SR^\"\" \nbijetora = T.is_bijective()\ninjetora = T.is_injective()\nsobrejetora = T.is_surjective()\ninverso= T.inverse()([x,y,z])\n\nif bijetora or (T*inverso):\n    print(T,\"é um isomorfismo\")\n    show(T*inverso)\nelse:\n    print(T, \"não é um isomorfismo\")\n    show(injetora)\n    show(sobrejetora)\n```\n\n</details>","date":"2024-04-29T23:20:13.077Z"}],"sender_id":"57ec71b6-a18b-44c0-a581-818804af3b11"}
{"date":"2024-04-29T23:20:13.097Z","editing":{},"event":"chat","generating":false,"history":[{"author_id":"openai-gpt-3.5-turbo","content":"The error message indicates a TypeError when trying to convert a vector to a symbolic expression. It seems to be related to the use of the function vector() when defining the transformation S. \n\nYou can try defining S in a different way that avoids this conversion issue:\n\n```sage\nS = lambda x, y, z: vector([2*x-z, 2*x-3*y+4*z, 3*y+z])\n```\n\nReplace the line `S(x,y,z) = vector([2*x-z, 2*x-3*y+4*z, 3*y+z]);` with the lambda function definition above. This should help resolve the error.","date":"2024-04-29T23:20:15.945Z"}],"reply_to":"2024-04-29T23:20:13.077Z","sender_id":"openai-gpt-3.5-turbo"}
{"date":"2024-04-29T23:22:29.580Z","editing":{},"event":"chat","history":[{"author_id":"57ec71b6-a18b-44c0-a581-818804af3b11","content":"<span class=\"user-mention\" account-id=openai-gpt-3.5-turbo >@GPT-3.5</span> Help me fix my code.\n\n<details><summary>Context</summary>\n\nI ran a cell in a Sage Worksheet.\n\nI received the following error:\n\n```sage\nError in lines 7-7\nTraceback (most recent call last):\n  File \"/cocalc/lib/python3.11/site-packages/smc_sagews/sage_server.py\", line 1244, in execute\n    exec(\n  File \"\", line 1, in <module>\n  File \"/ext/sage/10.3/src/sage/modules/matrix_morphism.py\", line 621, in __mul__\n    return self.parent()(self.matrix() * R(right))\n                                         ^^^^^^^^\n  File \"sage/structure/parent.pyx\", line 901, in sage.structure.parent.Parent.__call__\n    return mor._call_(x)\n  File \"sage/structure/coerce_maps.pyx\", line 163, in sage.structure.coerce_maps.DefaultConvertMap_unique._call_\n    raise\n  File \"sage/structure/coerce_maps.pyx\", line 158, in sage.structure.coerce_maps.DefaultConvertMap_unique._call_\n    return C._element_constructor(x)\n  File \"sage/symbolic/ring.pyx\", line 376, in sage.symbolic.ring.SymbolicRing._element_constructor_\n    return new_Expression(self, x)\n  File \"sage/symbolic/expression.pyx\", line 13817, in sage.symbolic.expression.new_Expression\n    raise TypeError(f\"unable to convert {x!r} to a symbolic expression\")\nTypeError: unable to convert (5/12*x + 1/12*y + 1/12*z, 1/18*x - 1/18*y + 5/18*z, -1/6*x + 1/6*y + 1/6*z) to a symbolic expression\n\n```\n\nMy SageMath Worksheet contains:\n\n```sage\n#Verificando se uma transformação é isomorfismo e calculando a inversa\nS(x,y,z) =([2*x-z, 2*x-3*y+4*z, 3*y+z]); #Modificar aqui a transformação \nT = linear_transformation(SR^3,SR^3,S); #Modificar SR^\"\" \nbijetora = T.is_bijective()\ninjetora = T.is_injective()\nsobrejetora = T.is_surjective()\ninverso= T.inverse()([x,y,z])\nv = T*inverso\nif bijetora or v:\n    print(T,\"é um isomorfismo\")\n    \nelse:\n    print(T, \"não é um isomorfismo\")\n    show(injetora)\n    show(sobrejetora)\n```\n\n</details>","date":"2024-04-29T23:22:29.580Z"}],"sender_id":"57ec71b6-a18b-44c0-a581-818804af3b11"}
{"date":"2024-04-29T23:22:29.594Z","editing":{},"event":"chat","generating":false,"history":[{"author_id":"openai-gpt-3.5-turbo","content":"It seems that the error is related to converting the output of your matrix transformation into a symbolic expression, but the code provided does not show where this conversion is happening.\n\nTo help you fix your code, you may want to check where the conversion to a symbolic expression is taking place and ensure that the input data and operations are compatible. You can also try to simplify the expressions being used in your transformation.","date":"2024-04-29T23:22:31.851Z"}],"reply_to":"2024-04-29T23:22:29.580Z","sender_id":"openai-gpt-3.5-turbo"}