{"active":1714155507230,"date":0,"event":"draft","input":"","sender_id":"57ec71b6-a18b-44c0-a581-818804af3b11"}
{"date":"2024-04-21T21:21:28.060Z","editing":{},"event":"chat","history":[{"author_id":"57ec71b6-a18b-44c0-a581-818804af3b11","content":"<span class=\"user-mention\" account-id=openai-gpt-3.5-turbo >@GPT-3.5</span> Help me fix my code.\n\n<details><summary>Context</summary>\n\nI ran a cell in a Sage Worksheet.\n\nI received the following error:\n\n```sage\nError in lines 5-7\nTraceback (most recent call last):\n  File \"/cocalc/lib/python3.11/site-packages/smc_sagews/sage_server.py\", line 1245, in execute\n    compile(block + '\\n',\n  File \"<string>\", line 3\n    else is_subspace = True\n         ^^^^^^^^^^^\nSyntaxError: expected ':'\n\n```\n\nMy SageMath Worksheet contains:\n\n```sage\n# Definindo variáveis simbólicas\nvar('x1 y1 x2 y2 a b c d')\n\n# Criando os vetores\nv1 = vector([a*x1, b*y1])\nv2 = vector([c*x2, d*y2])\n\n# Verificando se os vetores formam um subespaço vetorial\nis_subspace = True\n\n# Verificação das propriedades\n# 1. O vetor nulo pertence ao conjunto\nif vector([0, 0]) not in [v1, v2]:\n    is_subspace = False\nelse is_subspace = True\n\n# 2. Fechamento sob adição\nif (v1 + v2) not in [v1, v2]:\n    is_subspace = False\n    \nelse is_subspace = True\n\n# 3. Fechamento sob multiplicação por escalar\nif (a * v1) not in [v1, v2]:\n    is_subspace = False\n    \nelse is_subspace = True\n\nif is_subspace:\n    print(\"O conjunto forma um subespaço vetorial em R^2.\")\nelse:\n    print(\"O conjunto não forma um subespaço vetorial em R^2.\")\n```\n\n</details>","date":"2024-04-21T21:21:28.060Z"}],"sender_id":"57ec71b6-a18b-44c0-a581-818804af3b11"}
{"date":"2024-04-21T21:21:28.071Z","editing":{},"event":"chat","generating":false,"history":[{"author_id":"openai-gpt-3.5-turbo","content":"The issue in your code is with the syntax of the `if...else` statements. In Python, the `else` statement must be associated with the `if` statement using a colon (`:`). Therefore, your code should be structured like this:\n\n```sage\n# Definindo variáveis simbólicas\nvar('x1 y1 x2 y2 a b c d')\n\n# Criando os vetores\nv1 = vector([a*x1, b*y1])\nv2 = vector([c*x2, d*y2])\n\n# Verificando se os vetores formam um subespaço vetorial\nis_subspace = True\n\n# Verificação das propriedades\n# 1. O vetor nulo pertence ao conjunto\nif vector([0, 0]) not in [v1, v2]:\n    is_subspace = False\nelse:\n    is_subspace = True\n\n# 2. Fechamento sob adição\nif (v1 + v2) not in [v1, v2]:\n    is_subspace = False\nelse:\n    is_subspace = True\n\n# 3. Fechamento sob multiplicação por escalar\nif (a * v1) not in [v1, v2]:\n    is_subspace = False\nelse:\n    is_subspace = True\n\nif is_subspace:\n    print(\"O conjunto forma um subespaço vetorial em R^2.\")\nelse:\n    print(\"O conjunto não forma um subespaço vetorial em R^2.\")\n```\n\nThis way, the `else` statements are correctly associated with the corresponding `if` statements.","date":"2024-04-21T21:21:34.447Z"}],"reply_to":"2024-04-21T21:21:28.060Z","sender_id":"openai-gpt-3.5-turbo"}
{"date":"2024-04-21T21:39:57.675Z","editing":{},"event":"chat","history":[{"author_id":"57ec71b6-a18b-44c0-a581-818804af3b11","content":"<span class=\"user-mention\" account-id=openai-gpt-3.5-turbo >@GPT-3.5</span> Help me fix my code.\n\n<details><summary>Context</summary>\n\nI ran a cell in a Sage Worksheet.\n\nI received the following error:\n\n```sage\nError in lines 3-3\nTraceback (most recent call last):\n  File \"sage/structure/category_object.pyx\", line 855, in sage.structure.category_object.CategoryObject.getattr_from_category\n    return self._cached_methods[name]\nKeyError: 'subespace'\n\nDuring handling of the above exception, another exception occurred:\n\nTraceback (most recent call last):\n  File \"/cocalc/lib/python3.11/site-packages/smc_sagews/sage_server.py\", line 1244, in execute\n    exec(\n  File \"\", line 1, in <module>\n  File \"sage/structure/category_object.pyx\", line 849, in sage.structure.category_object.CategoryObject.__getattr__\n    return self.getattr_from_category(name)\n  File \"sage/structure/category_object.pyx\", line 864, in sage.structure.category_object.CategoryObject.getattr_from_category\n    attr = getattr_from_other_class(self, cls, name)\n  File \"sage/cpython/getattr.pyx\", line 357, in sage.cpython.getattr.getattr_from_other_class\n    raise AttributeError(dummy_error_message)\nAttributeError: 'FreeModule_ambient_field_with_category' object has no attribute 'subespace'\n\n```\n\nMy SageMath Worksheet contains:\n\n```sage\n# Definindo variáveis simbólicas\nvar('x1 y1 x2 y2 a b c d h')\n\n# Criando o espaço e o subespaço\nV = AA^3\nW = V.subespace([2*x1, 3*y1],[x2 - y2, 4*y2]);W\n\n# Verificando se os vetores formam um subespaço vetorial\nis_subspace = True\n\n# Verificação das propriedades\n# 1. O vetor nulo pertence ao conjunto\nzero_vector = vector([0, 0])\nif zero_vector not in [v1, v2]:\n    is_subspace = False\n\n# 2. Fechamento sob adição\nif v1 + v2 not in [v1, v2]:\n    is_subspace = False\n\n# 3. Fechamento sob multiplicação por escalar\nh in (RR)\nif h * v1 not in [v1, v2]:\n    is_subspace = False\n\nif is_subspace:\n    print(\"O conjunto forma um subespaço vetorial em R^2.\")\nelse:\n    print(\"O conjunto não forma um subespaço vetorial em R^2.\")\n```\n\n</details>","date":"2024-04-21T21:39:57.675Z"}],"sender_id":"57ec71b6-a18b-44c0-a581-818804af3b11"}
{"date":"2024-04-21T21:39:57.696Z","editing":{},"event":"chat","generating":false,"history":[{"author_id":"openai-gpt-3.5-turbo","content":"The issue is a typo in your code. The method to create a subspace is `subspace` not `subespace`. Just change `subespace` to `subspace` and your code should work fine.","date":"2024-04-21T21:39:59.083Z"}],"reply_to":"2024-04-21T21:39:57.675Z","sender_id":"openai-gpt-3.5-turbo"}
{"date":"2024-04-21T21:40:22.056Z","editing":{},"event":"chat","history":[{"author_id":"57ec71b6-a18b-44c0-a581-818804af3b11","content":"<span class=\"user-mention\" account-id=openai-gpt-3.5-turbo >@GPT-3.5</span> Help me fix my code.\n\n<details><summary>Context</summary>\n\nI ran a cell in a Sage Worksheet.\n\nI received the following error:\n\n```sage\nError in lines 3-3\nTraceback (most recent call last):\n  File \"/ext/sage/10.3/src/sage/modules/free_module.py\", line 6534, in __init__\n    basis = [ambient(x) for x in basis]\n            ^^^^^^^^^^^^^^^^^^^^^^^^^^^\n  File \"/ext/sage/10.3/src/sage/modules/free_module.py\", line 6534, in <listcomp>\n    basis = [ambient(x) for x in basis]\n             ^^^^^^^^^^\n  File \"sage/structure/parent.pyx\", line 901, in sage.structure.parent.Parent.__call__\n    return mor._call_(x)\n  File \"sage/structure/coerce_maps.pyx\", line 163, in sage.structure.coerce_maps.DefaultConvertMap_unique._call_\n    raise\n  File \"sage/structure/coerce_maps.pyx\", line 158, in sage.structure.coerce_maps.DefaultConvertMap_unique._call_\n    return C._element_constructor(x)\n  File \"/ext/sage/10.3/src/sage/modules/free_module.py\", line 6401, in _element_constructor_\n    return FreeModule_generic_field._element_constructor_(self, e, *args, **kwds)\n           ^^^^^^^^^^^^^^^^^^^^^^^^^^^^^^^^^^^^^^^^^^^^^^^^^^^^^^^^^^^^^^^^^^^^^^^^^^\n  File \"/ext/sage/10.3/src/sage/modules/free_module.py\", line 1760, in submodule\n    V = self.span(gens, check=check, already_echelonized=already_echelonized)\n        ^^^^^^^^^^^^^^^^^^^^^^^^^^^^^^^^^^^^^^^^^^^^^^^^^^^^^^^^^^^^^^^^^^^^^\n  File \"/ext/sage/10.3/src/sage/modules/free_module.py\", line 1675, in span\n    return self._submodule_class(self.ambient_module(), gens, check=check, already_echelonized=already_echelonized)\n           ^^^^^^^^^^^^^^^^^^^^^^^^^^^^^^^^^^^^^^^^^^^^^^^^^^^^^^^^^^^^^^^^^^^^^^^^^^^^^^^^^^^^^^^^^^^^^^^^^^^^^^^^\n  File \"/ext/sage/10.3/src/sage/modules/free_module.py\", line 7961, in __init__\n    FreeModule_submodule_with_basis_field.__init__(self, ambient, basis=gens, check=check,\n  File \"/ext/sage/10.3/src/sage/modules/free_module.py\", line 7761, in __init__\n    FreeModule_submodule_with_basis_pid.__init__(\n  File \"/ext/sage/10.3/src/sage/modules/free_module.py\", line 6542, in __init__\n    raise TypeError(\"each element of basis must be in \"\nTypeError: each element of basis must be in the ambient vector space\n\n```\n\nMy SageMath Worksheet contains:\n\n```sage\n# Definindo variáveis simbólicas\nvar('x1 y1 x2 y2 a b c d h')\n\n# Criando o espaço e o subespaço\nV = AA^3\nW = V.subspace([2*x1, 3*y1],[x2 - y2, 4*y2]);W\n\n# Verificando se os vetores formam um subespaço vetorial\nis_subspace = True\n\n# Verificação das propriedades\n# 1. O vetor nulo pertence ao conjunto\nzero_vector = vector([0, 0])\nif zero_vector not in [v1, v2]:\n    is_subspace = False\n\n# 2. Fechamento sob adição\nif v1 + v2 not in [v1, v2]:\n    is_subspace = False\n\n# 3. Fechamento sob multiplicação por escalar\nh in (RR)\nif h * v1 not in [v1, v2]:\n    is_subspace = False\n\nif is_subspace:\n    print(\"O conjunto forma um subespaço vetorial em R^2.\")\nelse:\n    print(\"O conjunto não forma um subespaço vetorial em R^2.\")\n```\n\n</details>","date":"2024-04-21T21:40:22.056Z"}],"sender_id":"57ec71b6-a18b-44c0-a581-818804af3b11"}
{"date":"2024-04-21T21:40:22.068Z","editing":{},"event":"chat","generating":false,"history":[{"author_id":"openai-gpt-3.5-turbo","content":"The error in your code is due to the misuse of square brackets in the subspace definition. It should be fixed as follows:\n\nReplace:\n\n```sage\nW = V.subspace([2*x1, 3*y1],[x2 - y2, 4*y2]);W\n```\n\nwith:\n\n```sage\nW = V.subspace([2*x1, 3*y1, x2 - y2, 4*y2]);W\n```\n\nThis change ensures that the vectors are correctly passed as a single list in the `subspace` function, resolving the error related to the ambient vector space.","date":"2024-04-21T21:40:24.640Z"}],"reply_to":"2024-04-21T21:40:22.056Z","sender_id":"openai-gpt-3.5-turbo"}
{"date":"2024-04-21T21:46:50.630Z","editing":{},"event":"chat","history":[{"author_id":"57ec71b6-a18b-44c0-a581-818804af3b11","content":"<span class=\"user-mention\" account-id=openai-gpt-3.5-turbo >@GPT-3.5</span> Help me fix my code.\n\n<details><summary>Context</summary>\n\nI ran a cell in a Sage Worksheet.\n\nI received the following error:\n\n```sage\nError in lines 3-3\nTraceback (most recent call last):\n  File \"/ext/sage/10.3/src/sage/modules/free_module.py\", line 6534, in __init__\n    basis = [ambient(x) for x in basis]\n            ^^^^^^^^^^^^^^^^^^^^^^^^^^^\n  File \"/ext/sage/10.3/src/sage/modules/free_module.py\", line 6534, in <listcomp>\n    basis = [ambient(x) for x in basis]\n             ^^^^^^^^^^\n  File \"sage/structure/parent.pyx\", line 901, in sage.structure.parent.Parent.__call__\n    return mor._call_(x)\n  File \"sage/structure/coerce_maps.pyx\", line 163, in sage.structure.coerce_maps.DefaultConvertMap_unique._call_\n    raise\n  File \"sage/structure/coerce_maps.pyx\", line 158, in sage.structure.coerce_maps.DefaultConvertMap_unique._call_\n    return C._element_constructor(x)\n  File \"/ext/sage/10.3/src/sage/modules/free_module.py\", line 6401, in _element_constructor_\n    return FreeModule_generic_field._element_constructor_(self, e, *args, **kwds)\n           ^^^^^^^^^^^^^^^^^^^^^^^^^^^^^^^^^^^^^^^^^^^^^^^^^^^^^^^^^^^^^^^^^^^^^^^^^^\n  File \"/ext/sage/10.3/src/sage/modules/free_module.py\", line 1760, in submodule\n    V = self.span(gens, check=check, already_echelonized=already_echelonized)\n        ^^^^^^^^^^^^^^^^^^^^^^^^^^^^^^^^^^^^^^^^^^^^^^^^^^^^^^^^^^^^^^^^^^^^^\n  File \"/ext/sage/10.3/src/sage/modules/free_module.py\", line 1675, in span\n    return self._submodule_class(self.ambient_module(), gens, check=check, already_echelonized=already_echelonized)\n           ^^^^^^^^^^^^^^^^^^^^^^^^^^^^^^^^^^^^^^^^^^^^^^^^^^^^^^^^^^^^^^^^^^^^^^^^^^^^^^^^^^^^^^^^^^^^^^^^^^^^^^^^\n  File \"/ext/sage/10.3/src/sage/modules/free_module.py\", line 7961, in __init__\n    FreeModule_submodule_with_basis_field.__init__(self, ambient, basis=gens, check=check,\n  File \"/ext/sage/10.3/src/sage/modules/free_module.py\", line 7761, in __init__\n    FreeModule_submodule_with_basis_pid.__init__(\n  File \"/ext/sage/10.3/src/sage/modules/free_module.py\", line 6542, in __init__\n    raise TypeError(\"each element of basis must be in \"\nTypeError: each element of basis must be in the ambient vector space\n\n```\n\nMy SageMath Worksheet contains:\n\n```sage\n# Definindo variáveis simbólicas\nvar('x1 y1 x2 y2 a b c d h')\n\n# Criando o espaço e o subespaço\nV = AA^2\nW = V.subspace([2*x1, 3*y1], [x2 - y2, 4*y2])\n\nif W.is_subspace():\n    print(\"É um subespaço vetorial.\")\nelse:\n    print(\"Não é um subespaço vetorial.\")\n```\n\n</details>","date":"2024-04-21T21:46:50.630Z"}],"sender_id":"57ec71b6-a18b-44c0-a581-818804af3b11"}
{"date":"2024-04-21T21:46:50.647Z","editing":{},"event":"chat","generating":false,"history":[{"author_id":"openai-gpt-3.5-turbo","content":"It seems the issue lies in the syntax used to define the subspace `W`. It appears that the basis vectors `[2*x1, 3*y1]` and `[x2 - y2, 4*y2]` are not recognized correctly.\n\nTry defining the subspace `W` as follows:\n\n```sage\nW = V.subspace([vector([2*x1, 3*y1]), vector([x2 - y2, 4*y2])]\n``` \n\nThis should resolve the error you encountered.","date":"2024-04-21T21:46:52.958Z"}],"reply_to":"2024-04-21T21:46:50.630Z","sender_id":"openai-gpt-3.5-turbo"}
{"date":"2024-04-21T21:47:25.625Z","editing":{},"event":"chat","history":[{"author_id":"57ec71b6-a18b-44c0-a581-818804af3b11","content":"<span class=\"user-mention\" account-id=openai-gpt-3.5-turbo >@GPT-3.5</span> Help me fix my code.\n\n<details><summary>Context</summary>\n\nI ran a cell in a Sage Worksheet.\n\nI received the following error:\n\n```sage\nError in lines 3-3\nTraceback (most recent call last):\n  File \"/cocalc/lib/python3.11/site-packages/smc_sagews/sage_server.py\", line 1245, in execute\n    compile(block + '\\n',\n  File \"<string>\", line 1\n    W = V.subspace([vector([Integer(2)*x1, Integer(3)*y1]), vector([x2 - y2, Integer(4)*y2])]\n                  ^\nSyntaxError: '(' was never closed\n\n```\n\nMy SageMath Worksheet contains:\n\n```sage\n# Definindo variáveis simbólicas\nvar('x1 y1 x2 y2 a b c d h')\n\n# Criando o espaço e o subespaço\nV = AA^2\nW = V.subspace([vector([2*x1, 3*y1]), vector([x2 - y2, 4*y2])]\n\nif W.is_subspace():\n    print(\"É um subespaço vetorial.\")\nelse:\n    print(\"Não é um subespaço vetorial.\")\n```\n\n</details>","date":"2024-04-21T21:47:25.625Z"}],"sender_id":"57ec71b6-a18b-44c0-a581-818804af3b11"}
{"date":"2024-04-21T21:47:25.636Z","editing":{},"event":"chat","generating":false,"history":[{"author_id":"openai-gpt-3.5-turbo","content":"It seems like you are missing a closing parenthesis in the line where you define the subspace W. \n\nYou should correct this line to:\n\n```sage\nW = V.subspace([vector([2*x1, 3*y1]), vector([x2 - y2, 4*y2])])\n```","date":"2024-04-21T21:47:27.224Z"}],"reply_to":"2024-04-21T21:47:25.625Z","sender_id":"openai-gpt-3.5-turbo"}
{"date":"2024-04-21T21:47:46.974Z","editing":{},"event":"chat","history":[{"author_id":"57ec71b6-a18b-44c0-a581-818804af3b11","content":"<span class=\"user-mention\" account-id=openai-gpt-3.5-turbo >@GPT-3.5</span> Help me fix my code.\n\n<details><summary>Context</summary>\n\nI ran a cell in a Sage Worksheet.\n\nI received the following error:\n\n```sage\nError in lines 3-3\nTraceback (most recent call last):\n  File \"/cocalc/lib/python3.11/site-packages/smc_sagews/sage_server.py\", line 1244, in execute\n    exec(\n  File \"\", line 1, in <module>\n  File \"/ext/sage/10.3/src/sage/modules/free_module.py\", line 4709, in subspace\n    return self.submodule(gens, check=check, already_echelonized=already_echelonized)\n           ^^^^^^^^^^^^^^^^^^^^^^^^^^^^^^^^^^^^^^^^^^^^^^^^^^^^^^^^^^^^^^^^^^^^^^^^^^\n  File \"/ext/sage/10.3/src/sage/modules/free_module.py\", line 1760, in submodule\n    V = self.span(gens, check=check, already_echelonized=already_echelonized)\n        ^^^^^^^^^^^^^^^^^^^^^^^^^^^^^^^^^^^^^^^^^^^^^^^^^^^^^^^^^^^^^^^^^^^^^\n  File \"/ext/sage/10.3/src/sage/modules/free_module.py\", line 1675, in span\n    return self._submodule_class(self.ambient_module(), gens, check=check, already_echelonized=already_echelonized)\n           ^^^^^^^^^^^^^^^^^^^^^^^^^^^^^^^^^^^^^^^^^^^^^^^^^^^^^^^^^^^^^^^^^^^^^^^^^^^^^^^^^^^^^^^^^^^^^^^^^^^^^^^^\n  File \"/ext/sage/10.3/src/sage/modules/free_module.py\", line 7961, in __init__\n    FreeModule_submodule_with_basis_field.__init__(self, ambient, basis=gens, check=check,\n    return AlgebraicConverter(field)(ex)\n           ^^^^^^^^^^^^^^^^^^^^^^^^^^^^^\n  File \"/ext/sage/10.3/src/sage/symbolic/expression_conversions.py\", line 212, in __call__\n    return self.arithmetic(ex, operator)\n           ^^^^^^^^^^^^^^^^^^^^^^^^^^^^^\n  File \"/ext/sage/10.3/src/sage/symbolic/expression_conversion_algebraic.py\", line 116, in arithmetic\n    return reduce(operator, map(self, ex.operands()))\n           ^^^^^^^^^^^^^^^^^^^^^^^^^^^^^^^^^^^^^^^^^^\n  File \"/ext/sage/10.3/src/sage/symbolic/expression_conversions.py\", line 206, in __call__\n    return self.symbol(ex)\n           ^^^^^^^^^^^^^^^\n  File \"/ext/sage/10.3/src/sage/symbolic/expression_conversions.py\", line 314, in symbol\n    raise NotImplementedError(\"symbol\")\nNotImplementedError: symbol\n\n```\n\nMy SageMath Worksheet contains:\n\n```sage\n# Definindo variáveis simbólicas\nvar('x1 y1 x2 y2 a b c d h')\n\n# Criando o espaço e o subespaço\nV = AA^2\nW = V.subspace([vector([2*x1, 3*y1]), vector([x2 - y2, 4*y2])])\n\nif W.is_subspace():\n    print(\"É um subespaço vetorial.\")\nelse:\n    print(\"Não é um subespaço vetorial.\")\n```\n\n</details>","date":"2024-04-21T21:47:46.974Z"}],"sender_id":"57ec71b6-a18b-44c0-a581-818804af3b11"}
{"date":"2024-04-21T21:47:46.982Z","editing":{},"event":"chat","generating":false,"history":[{"author_id":"openai-gpt-3.5-turbo","content":"It seems like an issue with creating the subspace in your code. Make sure to define the ambient space properly and check the syntax for defining subspaces. Here is a corrected version of your code:\n\n```sage\n# Definindo variáveis simbólicas\nvar('x1 y1 x2 y2')\n# Criando o espaço e o subespaço\nV = VectorSpace(AA, 2, 'v')\nW = V.subspace([vector([2*x1, 3*y1]), vector([x2 - y2, 4*y2])])\n\nif W.is_subspace():\n    print(\"É um subespaço vetorial.\")\nelse:\n    print(\"Não é um subespaço vetorial.\")\n```","date":"2024-04-21T21:47:50.767Z"}],"reply_to":"2024-04-21T21:47:46.974Z","sender_id":"openai-gpt-3.5-turbo"}
{"date":"2024-04-21T21:48:41.771Z","editing":{},"event":"chat","history":[{"author_id":"57ec71b6-a18b-44c0-a581-818804af3b11","content":"<span class=\"user-mention\" account-id=openai-gpt-3.5-turbo >@GPT-3.5</span> Help me fix my code.\n\n<details><summary>Context</summary>\n\nI ran a cell in a Sage Worksheet.\n\nI received the following error:\n\n```sage\nError in lines 2-2\nTraceback (most recent call last):\n  File \"/cocalc/lib/python3.11/site-packages/smc_sagews/sage_server.py\", line 1244, in execute\n    exec(\n  File \"\", line 1, in <module>\n  File \"/ext/sage/10.3/src/sage/modules/free_module.py\", line 581, in VectorSpace\n    raise TypeError(\"Argument sparse (= %s) must be a boolean.\" % sparse)\nTypeError: Argument sparse (= v) must be a boolean.\n\n```\n\nMy SageMath Worksheet contains:\n\n```sage\n# Definindo variáveis simbólicas\nvar('x1 y1 x2 y2')\n# Criando o espaço e o subespaço\nV = VectorSpace(AA, 2, 'v')\nW = V.subspace([vector([2*x1, 3*y1]), vector([x2 - y2, 4*y2])])\n\nif W.is_subspace():\n    print(\"É um subespaço vetorial.\")\nelse:\n    print(\"Não é um subespaço vetorial.\")\n```\n\n</details>","date":"2024-04-21T21:48:41.771Z"}],"sender_id":"57ec71b6-a18b-44c0-a581-818804af3b11"}
{"date":"2024-04-21T21:48:41.791Z","editing":{},"event":"chat","generating":false,"history":[{"author_id":"openai-gpt-3.5-turbo","content":"The error you are encountering is due to using 'v' as the argument for the sparse parameter in the VectorSpace function. This parameter should be a boolean value. Modify your code by specifying a boolean value for the sparse parameter in the VectorSpace function. For instance, updating the line where you define the vector space V as follows:\n\n```sage\nV = VectorSpace(AA, 2, sparse=False)\n``` \n\nThis change should resolve the error and allow your code to run correctly.","date":"2024-04-21T21:48:43.852Z"}],"reply_to":"2024-04-21T21:48:41.771Z","sender_id":"openai-gpt-3.5-turbo"}
{"date":"2024-04-21T21:49:12.930Z","editing":{},"event":"chat","history":[{"author_id":"57ec71b6-a18b-44c0-a581-818804af3b11","content":"<span class=\"user-mention\" account-id=openai-gpt-3.5-turbo >@GPT-3.5</span> Help me fix my code.\n\n<details><summary>Context</summary>\n\nI ran a cell in a Sage Worksheet.\n\nI received the following error:\n\n```sage\nError in lines 3-3\nTraceback (most recent call last):\n  File \"/cocalc/lib/python3.11/site-packages/smc_sagews/sage_server.py\", line 1244, in execute\n    exec(\n  File \"\", line 1, in <module>\n  File \"/ext/sage/10.3/src/sage/modules/free_module.py\", line 4709, in subspace\n    return self.submodule(gens, check=check, already_echelonized=already_echelonized)\n           ^^^^^^^^^^^^^^^^^^^^^^^^^^^^^^^^^^^^^^^^^^^^^^^^^^^^^^^^^^^^^^^^^^^^^^^^^^\n  File \"/ext/sage/10.3/src/sage/modules/free_module.py\", line 1760, in submodule\n    V = self.span(gens, check=check, already_echelonized=already_echelonized)\n        ^^^^^^^^^^^^^^^^^^^^^^^^^^^^^^^^^^^^^^^^^^^^^^^^^^^^^^^^^^^^^^^^^^^^^\n  File \"/ext/sage/10.3/src/sage/modules/free_module.py\", line 1675, in span\n    return self._submodule_class(self.ambient_module(), gens, check=check, already_echelonized=already_echelonized)\n           ^^^^^^^^^^^^^^^^^^^^^^^^^^^^^^^^^^^^^^^^^^^^^^^^^^^^^^^^^^^^^^^^^^^^^^^^^^^^^^^^^^^^^^^^^^^^^^^^^^^^^^^^\n  File \"/ext/sage/10.3/src/sage/modules/free_module.py\", line 7961, in __init__\n    FreeModule_submodule_with_basis_field.__init__(self, ambient, basis=gens, check=check,\n    return AlgebraicConverter(field)(ex)\n           ^^^^^^^^^^^^^^^^^^^^^^^^^^^^^\n  File \"/ext/sage/10.3/src/sage/symbolic/expression_conversions.py\", line 212, in __call__\n    return self.arithmetic(ex, operator)\n           ^^^^^^^^^^^^^^^^^^^^^^^^^^^^^\n  File \"/ext/sage/10.3/src/sage/symbolic/expression_conversion_algebraic.py\", line 116, in arithmetic\n    return reduce(operator, map(self, ex.operands()))\n           ^^^^^^^^^^^^^^^^^^^^^^^^^^^^^^^^^^^^^^^^^^\n  File \"/ext/sage/10.3/src/sage/symbolic/expression_conversions.py\", line 206, in __call__\n    return self.symbol(ex)\n           ^^^^^^^^^^^^^^^\n  File \"/ext/sage/10.3/src/sage/symbolic/expression_conversions.py\", line 314, in symbol\n    raise NotImplementedError(\"symbol\")\nNotImplementedError: symbol\n\n```\n\nMy SageMath Worksheet contains:\n\n```sage\n# Definindo variáveis simbólicas\nvar('x1 y1 x2 y2')\n# Criando o espaço e o subespaço\nV = VectorSpace(AA, 2, sparse=False)\nW = V.subspace([vector([2*x1, 3*y1]), vector([x2 - y2, 4*y2])])\n\nif W.is_subspace():\n    print(\"É um subespaço vetorial.\")\nelse:\n    print(\"Não é um subespaço vetorial.\")\n```\n\n</details>","date":"2024-04-21T21:49:12.930Z"}],"sender_id":"57ec71b6-a18b-44c0-a581-818804af3b11"}
{"date":"2024-04-21T21:49:12.955Z","editing":{},"event":"chat","generating":false,"history":[{"author_id":"openai-gpt-3.5-turbo","content":"The error you are encountering is due to the missing import statement for the `VectorSpace` class in your code. To fix the code, add the following import statement at the beginning:\n\n```sage\nfrom sage.modules.free_module import VectorSpace\n```\n\nOnce you add this import statement, your code should work correctly.","date":"2024-04-21T21:49:14.537Z"}],"reply_to":"2024-04-21T21:49:12.930Z","sender_id":"openai-gpt-3.5-turbo"}
{"date":"2024-04-21T21:49:37.987Z","editing":{},"event":"chat","history":[{"author_id":"57ec71b6-a18b-44c0-a581-818804af3b11","content":"<span class=\"user-mention\" account-id=openai-gpt-3.5-turbo >@GPT-3.5</span> Help me fix my code.\n\n<details><summary>Context</summary>\n\nI ran a cell in a Sage Worksheet.\n\nI received the following error:\n\n```sage\nError in lines 4-4\nTraceback (most recent call last):\n  File \"/cocalc/lib/python3.11/site-packages/smc_sagews/sage_server.py\", line 1244, in execute\n    exec(\n  File \"\", line 1, in <module>\n  File \"/ext/sage/10.3/src/sage/modules/free_module.py\", line 4709, in subspace\n    return self.submodule(gens, check=check, already_echelonized=already_echelonized)\n           ^^^^^^^^^^^^^^^^^^^^^^^^^^^^^^^^^^^^^^^^^^^^^^^^^^^^^^^^^^^^^^^^^^^^^^^^^^\n  File \"/ext/sage/10.3/src/sage/modules/free_module.py\", line 1760, in submodule\n    V = self.span(gens, check=check, already_echelonized=already_echelonized)\n        ^^^^^^^^^^^^^^^^^^^^^^^^^^^^^^^^^^^^^^^^^^^^^^^^^^^^^^^^^^^^^^^^^^^^^\n  File \"/ext/sage/10.3/src/sage/modules/free_module.py\", line 1675, in span\n    return self._submodule_class(self.ambient_module(), gens, check=check, already_echelonized=already_echelonized)\n           ^^^^^^^^^^^^^^^^^^^^^^^^^^^^^^^^^^^^^^^^^^^^^^^^^^^^^^^^^^^^^^^^^^^^^^^^^^^^^^^^^^^^^^^^^^^^^^^^^^^^^^^^\n  File \"/ext/sage/10.3/src/sage/modules/free_module.py\", line 7961, in __init__\n    FreeModule_submodule_with_basis_field.__init__(self, ambient, basis=gens, check=check,\n    return AlgebraicConverter(field)(ex)\n           ^^^^^^^^^^^^^^^^^^^^^^^^^^^^^\n  File \"/ext/sage/10.3/src/sage/symbolic/expression_conversions.py\", line 212, in __call__\n    return self.arithmetic(ex, operator)\n           ^^^^^^^^^^^^^^^^^^^^^^^^^^^^^\n  File \"/ext/sage/10.3/src/sage/symbolic/expression_conversion_algebraic.py\", line 116, in arithmetic\n    return reduce(operator, map(self, ex.operands()))\n           ^^^^^^^^^^^^^^^^^^^^^^^^^^^^^^^^^^^^^^^^^^\n  File \"/ext/sage/10.3/src/sage/symbolic/expression_conversions.py\", line 206, in __call__\n    return self.symbol(ex)\n           ^^^^^^^^^^^^^^^\n  File \"/ext/sage/10.3/src/sage/symbolic/expression_conversions.py\", line 314, in symbol\n    raise NotImplementedError(\"symbol\")\nNotImplementedError: symbol\n\n```\n\nMy SageMath Worksheet contains:\n\n```sage\nfrom sage.modules.free_module import VectorSpace\n# Definindo variáveis simbólicas\nvar('x1 y1 x2 y2')\n# Criando o espaço e o subespaço\nV = VectorSpace(AA, 2, sparse=False)\nW = V.subspace([vector([2*x1, 3*y1]), vector([x2 - y2, 4*y2])])\n\nif W.is_subspace():\n    print(\"É um subespaço vetorial.\")\nelse:\n    print(\"Não é um subespaço vetorial.\")\n```\n\n</details>","date":"2024-04-21T21:49:37.987Z"}],"sender_id":"57ec71b6-a18b-44c0-a581-818804af3b11"}
{"date":"2024-04-21T21:49:38.018Z","editing":{},"event":"chat","generating":false,"history":[{"author_id":"openai-gpt-3.5-turbo","content":"It seems there is an issue with the `VectorSpace` module in SageMath. Try using the `VectorSpace` command directly and see if that resolves the error. Here is the updated code snippet:\n\n```sage\n# Defining symbolic variables\nvar('x1 y1 x2 y2')\n# Defining the vector space and the subspace\nV = VectorSpace(RR, 2)\nW = V.subspace([vector([2*x1, 3*y1]), vector([x2 - y2, 4*y2])])\n\nif W.is_subspace():\n    print(\"It is a vector subspace.\")\nelse:\n    print(\"It is not a vector subspace.\")\n```","date":"2024-04-21T21:49:41.021Z"}],"reply_to":"2024-04-21T21:49:37.987Z","sender_id":"openai-gpt-3.5-turbo"}
{"date":"2024-04-21T21:50:12.714Z","editing":{},"event":"chat","history":[{"author_id":"57ec71b6-a18b-44c0-a581-818804af3b11","content":"<span class=\"user-mention\" account-id=openai-gpt-3.5-turbo >@GPT-3.5</span> Help me fix my code.\n\n<details><summary>Context</summary>\n\nI ran a cell in a Sage Worksheet.\n\nI received the following error:\n\n```sage\nError in lines 2-2\nTraceback (most recent call last):\n  File \"sage/modules/free_module_element.pyx\", line 4367, in sage.modules.free_module_element.FreeModuleElement_generic_dense.__init__\n    entries = [coefficient_ring(x) for x in entries]\n  File \"sage/structure/parent.pyx\", line 901, in sage.structure.parent.Parent.__call__\n    return mor._call_(x)\n  File \"sage/structure/coerce_maps.pyx\", line 292, in sage.structure.coerce_maps.NamedConvertMap._call_\n    cdef Element e = method(C)\n  File \"sage/symbolic/expression.pyx\", line 1723, in sage.symbolic.expression.Expression._mpfr_\n    return self._eval_self(R)\n  File \"sage/symbolic/expression.pyx\", line 1639, in sage.symbolic.expression.Expression._eval_self\n    raise TypeError(\"cannot evaluate symbolic expression to a numeric value\")\nTypeError: cannot evaluate symbolic expression to a numeric value\n\nDuring handling of the above exception, another exception occurred:\n\n           ^^^^^^^^^^^^^^^^^^^^^^^^^^^^^^^^^^^^^^^^^^^^^^^^^^^^^^^^^^^^^^^^^^^^^^^^^^\n  File \"/ext/sage/10.3/src/sage/modules/free_module.py\", line 1760, in submodule\n    V = self.span(gens, check=check, already_echelonized=already_echelonized)\n        ^^^^^^^^^^^^^^^^^^^^^^^^^^^^^^^^^^^^^^^^^^^^^^^^^^^^^^^^^^^^^^^^^^^^^\n  File \"/ext/sage/10.3/src/sage/modules/free_module.py\", line 1675, in span\n    return self._submodule_class(self.ambient_module(), gens, check=check, already_echelonized=already_echelonized)\n           ^^^^^^^^^^^^^^^^^^^^^^^^^^^^^^^^^^^^^^^^^^^^^^^^^^^^^^^^^^^^^^^^^^^^^^^^^^^^^^^^^^^^^^^^^^^^^^^^^^^^^^^^\n  File \"/ext/sage/10.3/src/sage/modules/free_module.py\", line 7961, in __init__\n    FreeModule_submodule_with_basis_field.__init__(self, ambient, basis=gens, check=check,\n  File \"/ext/sage/10.3/src/sage/modules/free_module.py\", line 7761, in __init__\n    FreeModule_submodule_with_basis_pid.__init__(\n  File \"/ext/sage/10.3/src/sage/modules/free_module.py\", line 6542, in __init__\n    raise TypeError(\"each element of basis must be in \"\nTypeError: each element of basis must be in the ambient vector space\n\n```\n\nMy SageMath Worksheet contains:\n\n```sage\nV = VectorSpace(RR, 2)\nW = V.subspace([vector([2*x1, 3*y1]), vector([x2 - y2, 4*y2])])\n\nif W.is_subspace():\n    print(\"It is a vector subspace.\")\nelse:\n    print(\"It is not a vector subspace.\")\n```\n\n</details>","date":"2024-04-21T21:50:12.714Z"}],"sender_id":"57ec71b6-a18b-44c0-a581-818804af3b11"}
{"date":"2024-04-21T21:50:12.747Z","editing":{},"event":"chat","generating":false,"history":[{"author_id":"openai-gpt-3.5-turbo","content":"The error suggests that the vectors provided in the `subspace` function call are not in the ambient vector space `V`. Double-check the construction of the vectors to ensure they belong to the same ambient space. Additionally, verify that the coefficients `x1, y1, x2, y2` are correctly defined or substituted before creating the vectors.","date":"2024-04-21T21:50:14.453Z"}],"reply_to":"2024-04-21T21:50:12.714Z","sender_id":"openai-gpt-3.5-turbo"}
{"date":"2024-04-21T21:52:44.720Z","editing":{},"event":"chat","history":[{"author_id":"57ec71b6-a18b-44c0-a581-818804af3b11","content":"<span class=\"user-mention\" account-id=openai-gpt-3.5-turbo >@GPT-3.5</span> Help me fix my code.\n\n<details><summary>Context</summary>\n\nI ran a cell in a Sage Worksheet.\n\nI received the following error:\n\n```sage\nError in lines 4-7\nTraceback (most recent call last):\n  File \"/cocalc/lib/python3.11/site-packages/smc_sagews/sage_server.py\", line 1244, in execute\n    exec(\n  File \"\", line 1, in <module>\nTypeError: FreeModule_generic_field.is_subspace() missing 1 required positional argument: 'other'\n\n```\n\nMy SageMath Worksheet contains:\n\n```sage\n# Definindo variáveis simbólicas\nvar('x1 y1 x2 y2')\n\n# Criando o espaço e o subespaço\nV = VectorSpace(RR, 2)\nW = V.subspace([vector([0, 1]), vector([1, 0])])\n\nif W.is_subspace():\n    print(\"É um subespaço vetorial.\")\nelse:\n    print(\"Não é um subespaço vetorial.\")\n```\n\n</details>","date":"2024-04-21T21:52:44.720Z"}],"sender_id":"57ec71b6-a18b-44c0-a581-818804af3b11"}
{"date":"2024-04-21T21:52:44.738Z","editing":{},"event":"chat","generating":false,"history":[{"author_id":"openai-gpt-3.5-turbo","content":"The issue in your code is that the `is_subspace()` method requires an argument specifying the subspace to check. You need to pass the subspace `W` as an argument to the `is_subspace()` method like this:\n\n```sage\nif W.is_subspace(W):\n```","date":"2024-04-21T21:52:46.451Z"}],"reply_to":"2024-04-21T21:52:44.720Z","sender_id":"openai-gpt-3.5-turbo"}
{"date":"2024-04-21T21:53:39.147Z","editing":{},"event":"chat","history":[{"author_id":"57ec71b6-a18b-44c0-a581-818804af3b11","content":"<span class=\"user-mention\" account-id=openai-gpt-3.5-turbo >@GPT-3.5</span> Help me fix my code.\n\n<details><summary>Context</summary>\n\nI ran a cell in a Sage Worksheet.\n\nI received the following error:\n\n```sage\nError in lines 3-3\nTraceback (most recent call last):\n  File \"sage/modules/free_module_element.pyx\", line 4367, in sage.modules.free_module_element.FreeModuleElement_generic_dense.__init__\n    entries = [coefficient_ring(x) for x in entries]\n  File \"sage/structure/parent.pyx\", line 901, in sage.structure.parent.Parent.__call__\n    return mor._call_(x)\n  File \"sage/structure/coerce_maps.pyx\", line 292, in sage.structure.coerce_maps.NamedConvertMap._call_\n    cdef Element e = method(C)\n  File \"sage/symbolic/expression.pyx\", line 1723, in sage.symbolic.expression.Expression._mpfr_\n    return self._eval_self(R)\n  File \"sage/symbolic/expression.pyx\", line 1639, in sage.symbolic.expression.Expression._eval_self\n    raise TypeError(\"cannot evaluate symbolic expression to a numeric value\")\nTypeError: cannot evaluate symbolic expression to a numeric value\n\nDuring handling of the above exception, another exception occurred:\n\n           ^^^^^^^^^^^^^^^^^^^^^^^^^^^^^^^^^^^^^^^^^^^^^^^^^^^^^^^^^^^^^^^^^^^^^^^^^^\n  File \"/ext/sage/10.3/src/sage/modules/free_module.py\", line 1760, in submodule\n    V = self.span(gens, check=check, already_echelonized=already_echelonized)\n        ^^^^^^^^^^^^^^^^^^^^^^^^^^^^^^^^^^^^^^^^^^^^^^^^^^^^^^^^^^^^^^^^^^^^^\n  File \"/ext/sage/10.3/src/sage/modules/free_module.py\", line 1675, in span\n    return self._submodule_class(self.ambient_module(), gens, check=check, already_echelonized=already_echelonized)\n           ^^^^^^^^^^^^^^^^^^^^^^^^^^^^^^^^^^^^^^^^^^^^^^^^^^^^^^^^^^^^^^^^^^^^^^^^^^^^^^^^^^^^^^^^^^^^^^^^^^^^^^^^\n  File \"/ext/sage/10.3/src/sage/modules/free_module.py\", line 7961, in __init__\n    FreeModule_submodule_with_basis_field.__init__(self, ambient, basis=gens, check=check,\n  File \"/ext/sage/10.3/src/sage/modules/free_module.py\", line 7761, in __init__\n    FreeModule_submodule_with_basis_pid.__init__(\n  File \"/ext/sage/10.3/src/sage/modules/free_module.py\", line 6542, in __init__\n    raise TypeError(\"each element of basis must be in \"\nTypeError: each element of basis must be in the ambient vector space\n\n```\n\nMy SageMath Worksheet contains:\n\n```sage\n# Definindo variáveis simbólicas\nvar('x1 y1 x2 y2')\n\n# Criando o espaço e o subespaço\nV = VectorSpace(RR, 2)\nW = V.subspace([vector([x1, 1]), vector([1, x2])])\nif W.is_subspace(W):\n    print(\"É um subespaço vetorial.\")\nelse:\n    print(\"Não é um subespaço vetorial.\")\n```\n\n</details>","date":"2024-04-21T21:53:39.147Z"}],"sender_id":"57ec71b6-a18b-44c0-a581-818804af3b11"}
{"date":"2024-04-21T21:53:39.167Z","editing":{},"event":"chat","generating":false,"history":[{"author_id":"openai-gpt-3.5-turbo","content":"The error is in the line `if W.is_subspace(W):`. \nIt should be `if W.is_subspace(V):` \n\nThis will correctly check if the subspace W is a subspace of the vector space V.","date":"2024-04-21T21:53:40.679Z"}],"reply_to":"2024-04-21T21:53:39.147Z","sender_id":"openai-gpt-3.5-turbo"}
{"date":"2024-04-21T22:00:20.855Z","editing":{},"event":"chat","history":[{"author_id":"57ec71b6-a18b-44c0-a581-818804af3b11","content":"<span class=\"user-mention\" account-id=openai-gpt-3.5-turbo >@GPT-3.5</span> Help me fix my code.\n\n<details><summary>Context</summary>\n\nI ran a cell in a Sage Worksheet.\n\nI received the following error:\n\n```sage\nError in lines 2-2\nTraceback (most recent call last):\n  File \"/ext/sage/10.3/src/sage/modules/free_module.py\", line 6534, in __init__\n    basis = [ambient(x) for x in basis]\n            ^^^^^^^^^^^^^^^^^^^^^^^^^^^\n  File \"/ext/sage/10.3/src/sage/modules/free_module.py\", line 6534, in <listcomp>\n    basis = [ambient(x) for x in basis]\n             ^^^^^^^^^^\n  File \"sage/structure/parent.pyx\", line 901, in sage.structure.parent.Parent.__call__\n    return mor._call_(x)\n  File \"sage/structure/coerce_maps.pyx\", line 163, in sage.structure.coerce_maps.DefaultConvertMap_unique._call_\n    raise\n  File \"sage/structure/coerce_maps.pyx\", line 158, in sage.structure.coerce_maps.DefaultConvertMap_unique._call_\n    return C._element_constructor(x)\n  File \"/ext/sage/10.3/src/sage/modules/free_module.py\", line 6401, in _element_constructor_\n    return FreeModule_generic_field._element_constructor_(self, e, *args, **kwds)\n           ^^^^^^^^^^^^^^^^^^^^^^^^^^^^^^^^^^^^^^^^^^^^^^^^^^^^^^^^^^^^^^^^^^^^^^^^^^\n  File \"/ext/sage/10.3/src/sage/modules/free_module.py\", line 1760, in submodule\n    V = self.span(gens, check=check, already_echelonized=already_echelonized)\n        ^^^^^^^^^^^^^^^^^^^^^^^^^^^^^^^^^^^^^^^^^^^^^^^^^^^^^^^^^^^^^^^^^^^^^\n  File \"/ext/sage/10.3/src/sage/modules/free_module.py\", line 1675, in span\n    return self._submodule_class(self.ambient_module(), gens, check=check, already_echelonized=already_echelonized)\n           ^^^^^^^^^^^^^^^^^^^^^^^^^^^^^^^^^^^^^^^^^^^^^^^^^^^^^^^^^^^^^^^^^^^^^^^^^^^^^^^^^^^^^^^^^^^^^^^^^^^^^^^^\n  File \"/ext/sage/10.3/src/sage/modules/free_module.py\", line 7961, in __init__\n    FreeModule_submodule_with_basis_field.__init__(self, ambient, basis=gens, check=check,\n  File \"/ext/sage/10.3/src/sage/modules/free_module.py\", line 7761, in __init__\n    FreeModule_submodule_with_basis_pid.__init__(\n  File \"/ext/sage/10.3/src/sage/modules/free_module.py\", line 6542, in __init__\n    raise TypeError(\"each element of basis must be in \"\nTypeError: each element of basis must be in the ambient vector space\n\n```\n\nMy SageMath Worksheet contains:\n\n```sage\n# Criando o espaço e o subespaço\nV = VectorSpace(RR, 3)\nW = V.subspace([[1,0],[0,1],[1,1]])\nif W.is_subspace([[1,0],[0,1],[1,1]]):\n    print(\"É um subespaço vetorial.\")\nelse:\n    print(\"Não é um subespaço vetorial.\")\n```\n\n</details>","date":"2024-04-21T22:00:20.855Z"}],"sender_id":"57ec71b6-a18b-44c0-a581-818804af3b11"}
{"date":"2024-04-21T22:00:20.876Z","editing":{},"event":"chat","generating":false,"history":[{"author_id":"openai-gpt-3.5-turbo","content":"The issue in your code is that the subspace `W` is being defined incorrectly. When creating a subspace, you need to specify vectors in the ambient space `V` that span the subspace `W`, not the actual elements of the subspace. \n\nHere's how you can fix it:\n\nChange:\n```sage\nW = V.subspace([[1,0],[0,1],[1,1]])\n```\nto:\n```sage\nW = V.subspace([V([1,0,0]), V([0,1,0]), V([1,1,0])])\n```\n\nThis should correctly define `W` as a subspace of `V` spanned by the given vectors.","date":"2024-04-21T22:00:24.494Z"}],"reply_to":"2024-04-21T22:00:20.855Z","sender_id":"openai-gpt-3.5-turbo"}
{"date":"2024-04-21T22:03:01.687Z","editing":{},"event":"chat","history":[{"author_id":"57ec71b6-a18b-44c0-a581-818804af3b11","content":"<span class=\"user-mention\" account-id=openai-gpt-3.5-turbo >@GPT-3.5</span> Help me fix my code.\n\n<details><summary>Context</summary>\n\nI ran a cell in a Sage Worksheet.\n\nI received the following error:\n\n```sage\nError in lines 6-9\nTraceback (most recent call last):\n  File \"/cocalc/lib/python3.11/site-packages/smc_sagews/sage_server.py\", line 1244, in execute\n    exec(\n  File \"\", line 1, in <module>\nTypeError: FreeModule_generic_field.is_subspace() missing 1 required positional argument: 'other'\n\n```\n\nMy SageMath Worksheet contains:\n\n```sage\n# Criando o espaço e o subespaço\nV = VectorSpace(RR, 3)\na = [1,0,0]\nb = [0,1,0]\nc = [1,1,0]\nW = V.subspace([V(a), V(b), V(c)])\nif W.is_subspace():\n    print(\"É um subespaço vetorial.\")\nelse:\n    print(\"Não é um subespaço vetorial.\")\n```\n\n</details>","date":"2024-04-21T22:03:01.687Z"}],"sender_id":"57ec71b6-a18b-44c0-a581-818804af3b11"}
{"date":"2024-04-21T22:03:01.703Z","editing":{},"event":"chat","generating":false,"history":[{"author_id":"openai-gpt-3.5-turbo","content":"It seems that the issue is with the `is_subspace()` method in SageMath. The error message indicates that the method is missing a required positional argument. \n\nTo fix this, you need to pass the vector space `V` as an argument to the `is_subspace()` method like this:\n\n```sage\nif W.is_subspace(V):\n    print(\"É um subespaço vetorial.\")\nelse:\n    print(\"Não é um subespaço vetorial.\")\n```\n\nThis should resolve the error and correctly check if `W` is a subspace of `V`.","date":"2024-04-21T22:03:04.209Z"}],"reply_to":"2024-04-21T22:03:01.687Z","sender_id":"openai-gpt-3.5-turbo"}
{"date":"2024-04-21T22:08:06.297Z","editing":{},"event":"chat","history":[{"author_id":"57ec71b6-a18b-44c0-a581-818804af3b11","content":"<span class=\"user-mention\" account-id=openai-gpt-3.5-turbo >@GPT-3.5</span> Help me fix my code.\n\n<details><summary>Context</summary>\n\nI ran a cell in a Sage Worksheet.\n\nI received the following error:\n\n```sage\nError in lines 6-9\nTraceback (most recent call last):\n  File \"/cocalc/lib/python3.11/site-packages/smc_sagews/sage_server.py\", line 1244, in execute\n    exec(\n  File \"\", line 1, in <module>\nTypeError: FreeModule_generic_field.is_subspace() missing 1 required positional argument: 'other'\n\n```\n\nMy SageMath Worksheet contains:\n\n```sage\nV = VectorSpace(RR, 2)\na = vector([1, 0])\nb = vector([5, 1])\nc = vector([5, -1])\nW = V.subspace([a, b, c])\nif W.is_subspace():\n    print(\"W é um subespaço de V.\")\nelse:\n    print(\"W não é um subespaço de V.\")\n```\n\n</details>","date":"2024-04-21T22:08:06.297Z"}],"sender_id":"57ec71b6-a18b-44c0-a581-818804af3b11"}
{"date":"2024-04-21T22:08:06.315Z","editing":{},"event":"chat","generating":false,"history":[{"author_id":"openai-gpt-3.5-turbo","content":"The issue in your code is that the `is_subspace` method of a subspace requires an argument, which is the vector space itself. You should modify the `if` statement to pass the vector space `V` as an argument to the `is_subspace` method.\n\nHere's the corrected code:\n\n```sage\nV = VectorSpace(RR, 2)\na = vector([1, 0])\nb = vector([5, 1])\nc = vector([5, -1])\nW = V.subspace([a, b, c])\nif W.is_subspace(V):\n    print(\"W é um subespaço de V.\")\nelse:\n    print(\"W não é um subespaço de V.\")\n```","date":"2024-04-21T22:08:11.667Z"}],"reply_to":"2024-04-21T22:08:06.297Z","sender_id":"openai-gpt-3.5-turbo"}
{"date":"2024-04-21T22:14:42.621Z","editing":{},"event":"chat","history":[{"author_id":"57ec71b6-a18b-44c0-a581-818804af3b11","content":"<span class=\"user-mention\" account-id=openai-gpt-3.5-turbo >@GPT-3.5</span> Help me fix my code.\n\n<details><summary>Context</summary>\n\nI ran a cell in a Sage Worksheet.\n\nI received the following error:\n\n```sage\nError in lines 1-1\nTraceback (most recent call last):\n  File \"/ext/sage/10.3/src/sage/modules/free_module.py\", line 6534, in __init__\n    basis = [ambient(x) for x in basis]\n            ^^^^^^^^^^^^^^^^^^^^^^^^^^^\n  File \"/ext/sage/10.3/src/sage/modules/free_module.py\", line 6534, in <listcomp>\n    basis = [ambient(x) for x in basis]\n             ^^^^^^^^^^\n  File \"sage/structure/parent.pyx\", line 901, in sage.structure.parent.Parent.__call__\n    return mor._call_(x)\n  File \"sage/structure/coerce_maps.pyx\", line 163, in sage.structure.coerce_maps.DefaultConvertMap_unique._call_\n    raise\n  File \"sage/structure/coerce_maps.pyx\", line 158, in sage.structure.coerce_maps.DefaultConvertMap_unique._call_\n    return C._element_constructor(x)\n  File \"/ext/sage/10.3/src/sage/modules/free_module.py\", line 6401, in _element_constructor_\n    return FreeModule_generic_field._element_constructor_(self, e, *args, **kwds)\n  File \"/ext/sage/10.3/src/sage/modules/free_module.py\", line 4801, in subspace_with_basis\n    return self.submodule_with_basis(gens, check=check, already_echelonized=already_echelonized)\n           ^^^^^^^^^^^^^^^^^^^^^^^^^^^^^^^^^^^^^^^^^^^^^^^^^^^^^^^^^^^^^^^^^^^^^^^^^^^^^^^^^^^^^\n  File \"/ext/sage/10.3/src/sage/modules/free_module.py\", line 4199, in submodule_with_basis\n    V = self.span_of_basis(basis=basis, check=check, already_echelonized=already_echelonized)\n        ^^^^^^^^^^^^^^^^^^^^^^^^^^^^^^^^^^^^^^^^^^^^^^^^^^^^^^^^^^^^^^^^^^^^^^^^^^^^^^^^^^^^^\n  File \"/ext/sage/10.3/src/sage/modules/free_module.py\", line 4653, in span_of_basis\n    return FreeModule_submodule_with_basis_field(\n           ^^^^^^^^^^^^^^^^^^^^^^^^^^^^^^^^^^^^^^\n  File \"/ext/sage/10.3/src/sage/modules/free_module.py\", line 7761, in __init__\n    FreeModule_submodule_with_basis_pid.__init__(\n  File \"/ext/sage/10.3/src/sage/modules/free_module.py\", line 6542, in __init__\n    raise TypeError(\"each element of basis must be in \"\nTypeError: each element of basis must be in the ambient vector space\n\n```\n\nMy SageMath Worksheet contains:\n\n```sage\n#Gerando base pro Subesapço Vetorial\n\nV.subspace_with_basis([1, 0, 0], [1,1,0])\n```\n\n</details>","date":"2024-04-21T22:14:42.621Z"}],"sender_id":"57ec71b6-a18b-44c0-a581-818804af3b11"}
{"date":"2024-04-21T22:14:42.647Z","editing":{},"event":"chat","generating":false,"history":[{"author_id":"openai-gpt-3.5-turbo","content":"The error indicates that each element of the basis must be in the ambient vector space. To fix the code, ensure that the basis elements belong to the vector space. Check the vector space definition and make sure the basis elements are valid vectors in that space.\n\n```sage\n#Gerando base pro Subespaço Vetorial\n\nV = <your_vector_space_definition>\nV.subspace_with_basis([<valid_vector_1>], [<valid_vector_2>])\n```","date":"2024-04-21T22:14:45.033Z"}],"reply_to":"2024-04-21T22:14:42.621Z","sender_id":"openai-gpt-3.5-turbo"}
{"date":"2024-04-21T22:18:23.979Z","editing":{},"event":"chat","history":[{"author_id":"57ec71b6-a18b-44c0-a581-818804af3b11","content":"<span class=\"user-mention\" account-id=openai-gpt-3.5-turbo >@GPT-3.5</span> Help me fix my code.\n\n<details><summary>Context</summary>\n\nI ran a cell in a Sage Worksheet.\n\nI received the following error:\n\n```sage\nError in lines 1-1\nTraceback (most recent call last):\n  File \"sage/structure/category_object.pyx\", line 855, in sage.structure.category_object.CategoryObject.getattr_from_category\n    return self._cached_methods[name]\nKeyError: 'is_field'\n\nDuring handling of the above exception, another exception occurred:\n\nTraceback (most recent call last):\n  File \"/cocalc/lib/python3.11/site-packages/smc_sagews/sage_server.py\", line 1244, in execute\n    exec(\n  File \"\", line 1, in <module>\n  File \"/ext/sage/10.3/src/sage/modules/free_module.py\", line 578, in VectorSpace\n    if not K.is_field():\n           ^^^^^^^^^^\n  File \"sage/structure/category_object.pyx\", line 849, in sage.structure.category_object.CategoryObject.__getattr__\n    return self.getattr_from_category(name)\n  File \"sage/structure/category_object.pyx\", line 864, in sage.structure.category_object.CategoryObject.getattr_from_category\n    attr = getattr_from_other_class(self, cls, name)\n  File \"sage/cpython/getattr.pyx\", line 357, in sage.cpython.getattr.getattr_from_other_class\n    raise AttributeError(dummy_error_message)\nAttributeError: 'FreeModule_ambient_field_with_category' object has no attribute 'is_field'\n\n```\n\nMy SageMath Worksheet contains:\n\n```sage\n#Gerando base pro Subesapço Vetorial\nV = VectorSpace(AA^3)\na = vector([1, 0, 0])\nb = vector([1, 1, 0])\nc = vector([0, 0, 1])\nV.subspace_with_basis([a], [b])\n```\n\n</details>","date":"2024-04-21T22:18:23.979Z"}],"sender_id":"57ec71b6-a18b-44c0-a581-818804af3b11"}
{"date":"2024-04-21T22:18:24.007Z","editing":{},"event":"chat","generating":false,"history":[{"author_id":"openai-gpt-3.5-turbo","content":"It seems that the issue is with the way you are defining the vector space and generating the subspace in your SageMath Worksheet.\n\nTry updating your code as follows:\n\n1. Replace the line:\n   ```sage\n   V = VectorSpace(AA^3)\n   ```\n   with:\n   ```sage\n   V = VectorSpace(AA, 3)\n   ```\n\n2. Modify the line:\n   ```sage\n   V.subspace_with_basis([a], [b])\n   ```\n   to:\n   ```sage\n   V.subspace_with_basis([a, b])\n   ```\n\nAfter making these changes, rerun the cell to see if the error is resolved. Let me know if you encounter any further issues.","date":"2024-04-21T22:18:26.681Z"}],"reply_to":"2024-04-21T22:18:23.979Z","sender_id":"openai-gpt-3.5-turbo"}
{"date":"2024-04-22T01:00:45.740Z","editing":{},"event":"chat","history":[{"author_id":"57ec71b6-a18b-44c0-a581-818804af3b11","content":"<span class=\"user-mention\" account-id=openai-gpt-3.5-turbo >@GPT-3.5</span> Help me fix my code.\n\n<details><summary>Context</summary>\n\nI ran a cell in a Sage Worksheet.\n\nI received the following error:\n\n```sage\nError in lines 13-13\nTraceback (most recent call last):\n  File \"/cocalc/lib/python3.11/site-packages/smc_sagews/sage_server.py\", line 1244, in execute\n    exec(\n  File \"\", line 1, in <module>\nNameError: name 'nova_base' is not defined\n\n```\n\nMy SageMath Worksheet contains:\n\n```sage\n# Mudança de Base\n\nR = RealField()\nV = VectorSpace(R, 3)\n\na = vector([1, 0, 0])\nb = vector([0, 1, 1])\nc = vector([0, 0, 1])\nbase = [a, b, c]\nshow(base)\n\nu1 = vector([1, 1, 0])\nu2 = vector([-1, 1, 0])\nu3 = vector([0, 0, 1])\nnov_base = [u1, u2, u3]\nshow(nov_base)\n# Criar a matriz de mudança de base P\nP = matrix(R, [V.coordinate_vector(u, base_original) for u in nova_base]).inverse()\n\n# Vetor na base original\nv = vector([3, 2, 1])\n\n# Calcular as coordenadas na nova base\ncoordenadas_nova_base = P * V.coordinate_vector(v, base_original)\n\nprint(\"Coordenadas na nova base:\", coordenadas_nova_base)\n```\n\n</details>","date":"2024-04-22T01:00:45.740Z"}],"sender_id":"57ec71b6-a18b-44c0-a581-818804af3b11"}
{"date":"2024-04-22T01:00:45.749Z","editing":{},"event":"chat","generating":false,"history":[{"author_id":"openai-gpt-3.5-turbo","content":"It seems there is a typo in your code. The variable `nov_base` is defined, but you are trying to access `nova_base` later in the code. Update `nova_base` to `nov_base` in the line calculating the matrix `P`.","date":"2024-04-22T01:00:47.770Z"}],"reply_to":"2024-04-22T01:00:45.740Z","sender_id":"openai-gpt-3.5-turbo"}
{"date":"2024-04-22T01:05:20.602Z","editing":{},"event":"chat","history":[{"author_id":"57ec71b6-a18b-44c0-a581-818804af3b11","content":"<span class=\"user-mention\" account-id=openai-gpt-3.5-turbo >@GPT-3.5</span> Help me fix my code.\n\n<details><summary>Context</summary>\n\nI ran a cell in a Sage Worksheet.\n\nI received the following error:\n\n```sage\nError in lines 13-13\nTraceback (most recent call last):\n  File \"/cocalc/lib/python3.11/site-packages/smc_sagews/sage_server.py\", line 1244, in execute\n    exec(\n  File \"\", line 1, in <module>\n  File \"\", line 1, in <listcomp>\nNameError: name 'base_original' is not defined\n\n```\n\nMy SageMath Worksheet contains:\n\n```sage\n# Mudança de Base\n\nR = RealField()\nV = VectorSpace(R, 3)\n\na = vector([1, 0, 0])\nb = vector([0, 1, 1])\nc = vector([0, 0, 1])\nbase = [a, b, c]\nshow(base)\n\nu1 = vector([1, 1, 0])\nu2 = vector([-1, 1, 0])\nu3 = vector([0, 0, 1])\nnov_base = [u1, u2, u3]\nshow(nov_base)\n# Criar a matriz de mudança de base P\nP = matrix(R, [V.coordinate_vector(u, base_original) for u in nov_base]).inverse()\n\n# Vetor na base original\nv = vector([3, 2, 1])\n\n# Calcular as coordenadas na nova base\ncoordenadas_nova_base = P * V.coordinate_vector(v, base_original)\n\nprint(\"Coordenadas na nova base:\", coordenadas_nova_base)\n```\n\n</details>","date":"2024-04-22T01:05:20.602Z"}],"sender_id":"57ec71b6-a18b-44c0-a581-818804af3b11"}
{"date":"2024-04-22T01:05:20.610Z","editing":{},"event":"chat","generating":false,"history":[{"author_id":"openai-gpt-3.5-turbo","content":"The error is due to `base_original` not being defined in your code. You should either define `base_original` or use `base` instead to fix the error.\n\nReplace `base_original` with `base` in the line:\n\n```sage\nP = matrix(R, [V.coordinate_vector(u, base) for u in nov_base]).inverse()\n```","date":"2024-04-22T01:05:23.401Z"}],"reply_to":"2024-04-22T01:05:20.602Z","sender_id":"openai-gpt-3.5-turbo"}
{"date":"2024-04-22T01:06:02.886Z","editing":{},"event":"chat","history":[{"author_id":"57ec71b6-a18b-44c0-a581-818804af3b11","content":"<span class=\"user-mention\" account-id=openai-gpt-3.5-turbo >@GPT-3.5</span> Help me fix my code.\n\n<details><summary>Context</summary>\n\nI ran a cell in a Sage Worksheet.\n\nI received the following error:\n\n```sage\nError in lines 15-15\nTraceback (most recent call last):\n  File \"/cocalc/lib/python3.11/site-packages/smc_sagews/sage_server.py\", line 1244, in execute\n    exec(\n  File \"\", line 1, in <module>\nNameError: name 'base_original' is not defined\n\n```\n\nMy SageMath Worksheet contains:\n\n```sage\n# Mudança de Base\n\nR = RealField()\nV = VectorSpace(R, 3)\n\na = vector([1, 0, 0])\nb = vector([0, 1, 1])\nc = vector([0, 0, 1])\nbase = [a, b, c]\nshow(base)\n\nu1 = vector([1, 1, 0])\nu2 = vector([-1, 1, 0])\nu3 = vector([0, 0, 1])\nnov_base = [u1, u2, u3]\nshow(nov_base)\n# Criar a matriz de mudança de base P\nP = matrix(R, [V.coordinate_vector(u, base) for u in nov_base]).inverse()\n\n# Vetor na base original\nv = vector([3, 2, 1])\n\n# Calcular as coordenadas na nova base\ncoordenadas_nova_base = P * V.coordinate_vector(v, base_original)\n\nprint(\"Coordenadas na nova base:\", coordenadas_nova_base)\n```\n\n</details>","date":"2024-04-22T01:06:02.886Z"}],"sender_id":"57ec71b6-a18b-44c0-a581-818804af3b11"}
{"date":"2024-04-22T01:06:02.898Z","editing":{},"event":"chat","generating":false,"history":[{"author_id":"openai-gpt-3.5-turbo","content":"The error message `NameError: name 'base_original' is not defined` indicates that the variable `base_original` is not defined in your code. You probably meant to use `base` instead of `base_original` when calculating the coordinates in the new base.\n\nChange `base_original` to `base` in the following line:\n\n```sage\ncoordenadas_nova_base = P * V.coordinate_vector(v, base_original)\n```\n\nto:\n\n```sage\ncoordenadas_nova_base = P * V.coordinate_vector(v, base)\n```","date":"2024-04-22T01:06:06.143Z"}],"reply_to":"2024-04-22T01:06:02.886Z","sender_id":"openai-gpt-3.5-turbo"}
{"date":"2024-04-22T01:09:37.075Z","editing":{},"event":"chat","history":[{"author_id":"57ec71b6-a18b-44c0-a581-818804af3b11","content":"<span class=\"user-mention\" account-id=openai-gpt-3.5-turbo >@GPT-3.5</span> Help me fix my code.\n\n<details><summary>Context</summary>\n\nI ran a cell in a Sage Worksheet.\n\nI received the following error:\n\n```sage\nError in lines 12-12\nTraceback (most recent call last):\n  File \"/ext/sage/10.3/src/sage/modules/free_module.py\", line 6170, in coordinate_vector\n    out = self.ambient_vector_space()._element_constructor_(v)\n          ^^^^^^^^^^^^^^^^^^^^^^^^^^^^^^^^^^^^^^^^^^^^^^^^^^^^\n  File \"/ext/sage/10.3/src/sage/modules/free_module.py\", line 6401, in _element_constructor_\n    return FreeModule_generic_field._element_constructor_(self, e, *args, **kwds)\n           ^^^^^^^^^^^^^^^^^^^^^^^^^^^^^^^^^^^^^^^^^^^^^^^^^^^^^^^^^^^^^^^^^^^^^^\n  File \"/ext/sage/10.3/src/sage/modules/free_module.py\", line 2193, in _element_constructor_\n    return self.element_class(self, x, coerce, copy)\n           ^^^^^^^^^^^^^^^^^^^^^^^^^^^^^^^^^^^^^^^^^\n  File \"sage/modules/free_module_element.pyx\", line 4363, in sage.modules.free_module_element.FreeModuleElement_generic_dense.__init__\n    raise TypeError(\"entries must be a list of length %s\" % self.degree())\nTypeError: entries must be a list of length 2\n\nDuring handling of the above exception, another exception occurred:\n\nTraceback (most recent call last):\n  File \"/cocalc/lib/python3.11/site-packages/smc_sagews/sage_server.py\", line 1244, in execute\n    exec(\n  File \"\", line 1, in <module>\n  File \"/ext/sage/10.3/src/sage/modules/free_module.py\", line 6172, in coordinate_vector\n    raise ArithmeticError(\"Error transforming the given vector into the ambient vector space\")\nArithmeticError: Error transforming the given vector into the ambient vector space\n\n```\n\nMy SageMath Worksheet contains:\n\n```sage\n# Mudança de Base\n\nV = VectorSpace(SR, 2)\n\na = vector([1, 0])\nb = vector([0, -1])\n#c = vector([0, 0])\nbase = [a, b]\nshow(base)\n\nu1 = vector([2, 0])\nu2 = vector([3, 1])\n#u3 = vector([0, 0, 1])\nnov_base = [u1, u2]\nshow(nov_base)\n# Criar a matriz de mudança de base P\nP = matrix(SR, [V.coordinate_vector(u, base) for u in nov_base]).inverse()\n\n# Vetor na base original\nv = vector([3, 2, 1])\n\n# Calcular as coordenadas na nova base\ncoordenadas_nova_base = P * V.coordinate_vector(v, base)\n\nprint(\"Coordenadas na nova base:\", coordenadas_nova_base)\n```\n\n</details>","date":"2024-04-22T01:09:37.075Z"}],"sender_id":"57ec71b6-a18b-44c0-a581-818804af3b11"}
{"date":"2024-04-22T01:09:37.086Z","editing":{},"event":"chat","generating":false,"history":[{"author_id":"openai-gpt-3.5-turbo","content":"The error is due to the mismatch in the dimensions of the vectors. \n\nIn the code snippet provided, the vector `v = vector([3, 2, 1])` is of dimension 3, while the vector space `V = VectorSpace(SR, 2)` is of dimension 2.\n\nTo fix the issue, you need to ensure that the vectors are of the correct dimension. You can either change the dimension of the vector space or adjust the dimensions of the vectors accordingly.","date":"2024-04-22T01:09:39.166Z"}],"reply_to":"2024-04-22T01:09:37.075Z","sender_id":"openai-gpt-3.5-turbo"}