{"active":1713659349513,"date":1713659329584,"event":"draft","input":"The error you are encountering seems to be related to trying to convert a symbolic expression to an integer. \n\nIn your code, there are two instances where you define the same variables within the same scope. This might be causing conflicts. Remove one of the variable declarations for x, y, z.\n\nAdditionally, check the solve method syntax. Ensure that the syntax for solving the system of equations is correct.\n\nYou may also want to check if the content inside the `if` statement is handling the solutions correctly when there is only one solution.\n\n```\nvar('x y z')\neq1 = 2*x + y - z == 1\neq2 = 2*x + y + 4*z == 2\neq3 = x + 2*y - 5*z == 3\n\nsolucao = solve([eq1, eq2, eq3], [x,y,z])\n\nif len(solucao) > 1:  \n    show(solucao[0][x])\n    show(solucao[0][y])\n    show(solucao[1][x])\n    show(solucao[1][y])\nelse:\n    show(solucao)\n\n#Resolvendo o sistema linear por matriz\n\nA = matrix([[2,1,-1], [2,1,4], [1,2,-5]])\nvetor = vector([1,2,3])\nsolucao = A.solve_right(vetor)\nsolucao\n```\n\n","sender_id":"57ec71b6-a18b-44c0-a581-818804af3b11"}
{"active":1716428421535,"date":0,"event":"draft","input":"","sender_id":"57ec71b6-a18b-44c0-a581-818804af3b11"}
{"date":"2024-04-20T18:46:42.776Z","editing":{},"event":"chat","history":[{"author_id":"57ec71b6-a18b-44c0-a581-818804af3b11","content":"<span class=\"user-mention\" account-id=openai-gpt-3.5-turbo >@GPT-3.5</span> Help me fix my code.\n\n<details><summary>Context</summary>\n\nI ran a cell in a Sage Worksheet.\n\nI received the following error:\n\n```sage\nError in lines 2-2\nTraceback (most recent call last):\n  File \"/cocalc/lib/python3.11/site-packages/smc_sagews/sage_server.py\", line 1244, in execute\n    exec(\n  File \"\", line 1, in <module>\nNameError: name 'v' is not defined\n\n```\n\nMy SageMath Worksheet contains:\n\n```sage\n\"\"\"\n\nParte 1 - Vetores\nIremos começar primeiramente como definir os vetores\n\n\"\"\"\n\nv1 = vector([1/2,1/2,-4/3]);v\n```\n\n</details>","date":"2024-04-20T18:46:42.776Z"}],"sender_id":"57ec71b6-a18b-44c0-a581-818804af3b11"}
{"date":"2024-04-20T18:46:42.795Z","editing":{},"event":"chat","generating":false,"history":[{"author_id":"openai-gpt-3.5-turbo","content":"It seems like you are trying to print vector `v`, but the variable `v` is not defined in your code. You probably meant to print `v1`, which is the vector you previously defined. Update `v` to `v1` in your code and try running the cell again.","date":"2024-04-20T18:46:45.791Z"}],"reply_to":"2024-04-20T18:46:42.776Z","sender_id":"openai-gpt-3.5-turbo"}
{"date":"2024-04-20T18:47:23.453Z","editing":{},"event":"chat","history":[{"author_id":"57ec71b6-a18b-44c0-a581-818804af3b11","content":"certo","date":"2024-04-20T18:47:23.453Z"}],"sender_id":"57ec71b6-a18b-44c0-a581-818804af3b11"}
{"date":"2024-04-20T19:00:31.898Z","editing":{},"event":"chat","history":[{"author_id":"57ec71b6-a18b-44c0-a581-818804af3b11","content":"<span class=\"user-mention\" account-id=openai-gpt-3.5-turbo >@GPT-3.5</span> Help me fix my code.\n\n<details><summary>Context</summary>\n\nI ran a cell in a Sage Worksheet.\n\nI received the following error:\n\n```sage\nError in lines 1-1\nTraceback (most recent call last):\n  File \"/cocalc/lib/python3.11/site-packages/smc_sagews/sage_server.py\", line 1244, in execute\n    exec(\n  File \"\", line 1, in <module>\n  File \"sage/modules/free_module_element.pyx\", line 534, in sage.modules.free_module_element.vector\n    if not isinstance(arg2, dict) and len(arg2) != degree:\nTypeError: object of type 'sage.rings.integer.Integer' has no len()\n\n```\n\nMy SageMath Worksheet contains:\n\n```sage\nv2 = vector(-2,2,4);v2\n\nsoma= v1+v2;soma\nv1-v2;\nk*v2; #Produto por escalar\nv1.cross_product(v2);\nv1.dot_product(v2);\n```\n\n</details>","date":"2024-04-20T19:00:31.898Z"}],"sender_id":"57ec71b6-a18b-44c0-a581-818804af3b11"}
{"date":"2024-04-20T19:00:31.935Z","editing":{},"event":"chat","generating":false,"history":[{"author_id":"openai-gpt-3.5-turbo","content":"The error `TypeError: object of type 'sage.rings.integer.Integer' has no len()` likely occurred because the `vector` function expects a dictionary for its second argument.\n\nTo fix the code, you need to create vectors using the `vector` function properly. Here's the corrected code:\n\n```sage\nv1 = vector([1, 2, 3])\nv2 = vector([-2, 2, 4])\nsoma = v1 + v2\nv1 - v2\nk * v2  # Scalar product\nv1.cross_product(v2)\nv1.dot_product(v2)\n```\n\nMake sure to define `v1` before using it.","date":"2024-04-20T19:00:36.128Z"}],"reply_to":"2024-04-20T19:00:31.898Z","sender_id":"openai-gpt-3.5-turbo"}
{"date":"2024-04-20T19:02:08.827Z","editing":{},"event":"chat","history":[{"author_id":"57ec71b6-a18b-44c0-a581-818804af3b11","content":"<span class=\"user-mention\" account-id=openai-gpt-3.5-turbo >@GPT-3.5</span> Help me fix my code.\n\n<details><summary>Context</summary>\n\nI ran a cell in a Sage Worksheet.\n\nI received the following error:\n\n```sage\nError in lines 5-5\nTraceback (most recent call last):\n  File \"/cocalc/lib/python3.11/site-packages/smc_sagews/sage_server.py\", line 1244, in execute\n    exec(\n  File \"\", line 1, in <module>\nNameError: name 'k' is not defined\n\n```\n\nMy SageMath Worksheet contains:\n\n```sage\nv1 = vector([1/2,1/2,-4/3]);v1\nv2 = vector([-2,2,4]);v2\n\nsoma= v1+v2;soma\nv1-v2;\nk*v2; #Produto por escalar\nv1.cross_product(v2);\nv1.dot_product(v2);\n```\n\n</details>","date":"2024-04-20T19:02:08.827Z"}],"sender_id":"57ec71b6-a18b-44c0-a581-818804af3b11"}
{"date":"2024-04-20T19:02:08.858Z","editing":{},"event":"chat","generating":false,"history":[{"author_id":"openai-gpt-3.5-turbo","content":"It seems like the variable 'k' is not defined in the code. You should define 'k' before using it to perform scalar multiplication with 'v2'.\n\nYou can fix the code by adding a line to define 'k' before using it:\n\n```sage\nv1 = vector([1/2,1/2,-4/3]);v1\nv2 = vector([-2,2,4]);v2\n\nsoma= v1+v2;soma\nv1-v2;\nk = 5  # Define k here\nk*v2; # Produto por escalar\nv1.cross_product(v2);\nv1.dot_product(v2);\n```","date":"2024-04-20T19:02:13.591Z"}],"reply_to":"2024-04-20T19:02:08.827Z","sender_id":"openai-gpt-3.5-turbo"}
{"date":"2024-04-20T19:04:53.679Z","editing":{},"event":"chat","history":[{"author_id":"57ec71b6-a18b-44c0-a581-818804af3b11","content":"how can i define \"K\" belong to the R","date":"2024-04-20T19:04:53.679Z"}],"sender_id":"57ec71b6-a18b-44c0-a581-818804af3b11"}
{"date":"2024-04-20T20:13:47.131Z","editing":{},"event":"chat","history":[{"author_id":"57ec71b6-a18b-44c0-a581-818804af3b11","content":"<span class=\"user-mention\" account-id=openai-gpt-3.5-turbo >@GPT-3.5</span> Help me fix my code.\n\n<details><summary>Context</summary>\n\nI ran a cell in a Sage Worksheet.\n\nI received the following error:\n\n```sage\nError in lines 1-1\nTraceback (most recent call last):\n  File \"/cocalc/lib/python3.11/site-packages/smc_sagews/sage_server.py\", line 1245, in execute\n    compile(block + '\\n',\n  File \"<string>\", line 1\n    \"\n    ^\nSyntaxError: unterminated string literal (detected at line 1)\n\n```\n\nMy SageMath Worksheet contains:\n\n```sage\n\"\nParte 3 - Criação de Matrizes comuns e especiais\n\n\"\n#Matrizes comuns:\n\nA = matrix([[1,2],[3,4],[5,6]]);A #Modo direto de criação\nB = matrix(3,2,[1,2,3,4,5,6]);B #Modo lista; (3,2) indica uma Matriz(MxN)3x2 [1,2,...,6]indica os elementos\n#Pode usar a ferramenta \"Linear\" que o CoCalc irá gerar uma matriz aletatória\n\n#Matrizes especiais:\n\nmatrix.zero(m,n) #Essa é a matriz nula, por favor trocar \"m\" e \"n\" por valores\n\nmatrix.identity(x) #Essa é a matriz identidade, por favor trocar \"x\" por algum número. Se por 3, então será uma matriz(3x3)\n\nmatrix.diagonal(x,y,z)# Essa é a matriz diagonal, troque os elementos \"x\",\"y\",\"z\" por números, e ele só aparecerão na diagonal\n\nmatrix.random(ZZ,m,n) #Código que gera matriz aleatória, ZZ pode ser trocado por outro conjunto numérico (NN,QQ,RR,CC), \"m\" representa a linha equanto \"n\" representa a coluna\n\nsparse_mat = sparse_matrix(ZZ, 5, 5, {(1, 1): 2, (2, 3): 5, (4, 0): -3})\nsparse_mat\n```\n\n</details>","date":"2024-04-20T20:13:47.131Z"}],"sender_id":"57ec71b6-a18b-44c0-a581-818804af3b11"}
{"date":"2024-04-20T20:13:47.140Z","editing":{},"event":"chat","generating":false,"history":[{"author_id":"openai-gpt-3.5-turbo","content":"It seems that the error is due to the unterminated string literal on line 1 of your code block. \n\nTo fix it, you need to make sure that the string is properly enclosed within double quotes. Here's the corrected version:\n\n```sage\n\"\"\"\nParte 3 - Criação de Matrizes comuns e especiais\n\"\"\"\n\n# Remaining code...\n\n```\n\nEnclosing the text within triple double quotes should resolve the issue.","date":"2024-04-20T20:13:49.918Z"}],"reply_to":"2024-04-20T20:13:47.131Z","sender_id":"openai-gpt-3.5-turbo"}
{"date":"2024-04-20T20:16:16.629Z","editing":{},"event":"chat","history":[{"author_id":"57ec71b6-a18b-44c0-a581-818804af3b11","content":"<span class=\"user-mention\" account-id=openai-gpt-3.5-turbo >@GPT-3.5</span> Help me fix my code.\n\n<details><summary>Context</summary>\n\nI ran a cell in a Sage Worksheet.\n\nI received the following error:\n\n```sage\nError in lines 4-4\nTraceback (most recent call last):\n  File \"/cocalc/lib/python3.11/site-packages/smc_sagews/sage_server.py\", line 1244, in execute\n    exec(\n  File \"\", line 1, in <module>\nNameError: name 'm' is not defined\n\n```\n\nMy SageMath Worksheet contains:\n\n```sage\n\"\"\"\nParte 3 - Criação de Matrizes comuns e especiais\n\n\"\"\"\n#Matrizes comuns:\n\nA = matrix([[1,2],[3,4],[5,6]]);A #Modo direto de criação\nB = matrix(3,2,[1,2,3,4,5,6]);B #Modo lista; (3,2) indica uma Matriz(MxN)3x2 [1,2,...,6]indica os elementos\n#Pode usar a ferramenta \"Linear\" que o CoCalc irá gerar uma matriz aletatória\n\n#Matrizes especiais:\n\nmnula = matrix.zero(m,n) #Essa é a matriz nula, por favor trocar \"m\" e \"n\" por valores\n\nmidentidade = matrix.identity(x) #Essa é a matriz identidade, por favor trocar \"x\" por algum número. Se por 3, então será uma matriz(3x3)\n\nmdiagonal = matrix.diagonal(x,y,z)# Essa é a matriz diagonal, troque os elementos \"x\",\"y\",\"z\" por números, e ele só aparecerão na diagonal\n\nmradom = matrix.random(ZZ,m,n) #Código que gera matriz aleatória, ZZ pode ser trocado por outro conjunto numérico (NN,QQ,RR,CC), \"m\" representa a linha equanto \"n\" representa a coluna\n\nsparse_mat = sparse_matrix(ZZ, 5, 5, {(1, 1): 2, (2, 3): 5, (4, 0): -3})\n\nmnula midentidade mdiagonal mradom sparse_mat\n```\n\n</details>","date":"2024-04-20T20:16:16.629Z"}],"sender_id":"57ec71b6-a18b-44c0-a581-818804af3b11"}
{"date":"2024-04-20T20:16:16.637Z","editing":{},"event":"chat","generating":false,"history":[{"author_id":"openai-gpt-3.5-turbo","content":"It seems like there is a typo where you defined variables \"mnula\", \"midentidade\", \"mdiagonal\", \"mradom\". The variable names should be corrected to match the respective function names \"mnula = matrix.zero(m,n)\", \"midentidade = matrix.identity(x)\", \"mdiagonal = matrix.diagonal(x,y,z)\", \"mradom = matrix.random(ZZ,m,n)\" in lines 16, 19, 22, and 25 respectively. Fixing these typos should resolve the \"NameError\" you encountered.","date":"2024-04-20T20:16:18.706Z"}],"reply_to":"2024-04-20T20:16:16.629Z","sender_id":"openai-gpt-3.5-turbo"}
{"date":"2024-04-20T20:40:23.325Z","editing":{},"event":"chat","history":[{"author_id":"57ec71b6-a18b-44c0-a581-818804af3b11","content":"<span class=\"user-mention\" account-id=openai-gpt-3.5-turbo >@GPT-3.5</span> Help me fix my code.\n\n<details><summary>Context</summary>\n\nI ran a cell in a Sage Worksheet.\n\nI received the following error:\n\n```sage\n\n\n*** WARNING: Code contains possible implicit multiplication    ***\n*** Check if any of [ 2I ] need a \"*\" sign for multiplication, e.g. 5x should be 5*x ! ***\n\nError in lines 3-3\nTraceback (most recent call last):\n  File \"/cocalc/lib/python3.11/site-packages/smc_sagews/sage_server.py\", line 1245, in execute\n    compile(block + '\\n',\n  File \"<string>\", line 1\n    B = matrix([[Integer(1), I], [-I, Integer(2)],[-2I,Integer(1)]])\n                                                    ^\nSyntaxError: invalid decimal literal\n\n```\n\nMy SageMath Worksheet contains:\n\n```sage\n\"\"\"\nParte 6 - Funções matriciais\n\"\"\"\n\n# Criando uma matriz\nA = matrix([[1, 2, 3], [4, 5, 6], [7, 8, 9]])\nB = matrix([[1, I], [-I, 2],[-2I,1]])\n# Calculando o determinante da matriz\ndeterminante = A.det()\n\n# Calculando a transposta da matriz\ntransposta = A.transpose()\n\n# Calculando a matriz inversa\ninversa = A.inverse()\n\n# Calculando a conjugada da matriz\nconjugada = B.conjugate()\n\ndeterminante, transposta, inversa, conjugada\n```\n\n</details>","date":"2024-04-20T20:40:23.325Z"}],"sender_id":"57ec71b6-a18b-44c0-a581-818804af3b11"}
{"date":"2024-04-20T20:40:23.333Z","editing":{},"event":"chat","generating":false,"history":[{"author_id":"openai-gpt-3.5-turbo","content":"It seems like the error is due to the way complex numbers are being represented in your SageMath code. \n\nFor the matrix `B`, you should represent complex numbers as `1*I` instead of `1I` or `-2*I` instead of `-2I`. \n\nYou need to use the asterisk symbol for multiplication when representing complex numbers like `I` in SageMath. \n\nHere is the corrected part of your code snippet:\n\n```sage\nB = matrix([[1, I], [-I, 2],[-2*I,1]])\n```","date":"2024-04-20T20:40:26.084Z"}],"reply_to":"2024-04-20T20:40:23.325Z","sender_id":"openai-gpt-3.5-turbo"}
{"date":"2024-04-20T20:41:39.907Z","editing":{},"event":"chat","history":[{"author_id":"57ec71b6-a18b-44c0-a581-818804af3b11","content":"<span class=\"user-mention\" account-id=openai-gpt-3.5-turbo >@GPT-3.5</span> Help me fix my code.\n\n<details><summary>Context</summary>\n\nI ran a cell in a Sage Worksheet.\n\nI received the following error:\n\n```sage\nError in lines 6-6\nTraceback (most recent call last):\n  File \"/cocalc/lib/python3.11/site-packages/smc_sagews/sage_server.py\", line 1244, in execute\n    exec(\n  File \"\", line 1, in <module>\n  File \"sage/matrix/matrix2.pyx\", line 10130, in sage.matrix.matrix2.Matrix.inverse\n    return ~self\n  File \"sage/matrix/matrix_integer_dense.pyx\", line 4159, in sage.matrix.matrix_integer_dense.Matrix_integer_dense.__invert__\n    A, d = self._invert_flint()\n  File \"sage/matrix/matrix_integer_dense.pyx\", line 4120, in sage.matrix.matrix_integer_dense.Matrix_integer_dense._invert_flint\n    raise ZeroDivisionError('matrix must be nonsingular')\nZeroDivisionError: matrix must be nonsingular\n\n```\n\nMy SageMath Worksheet contains:\n\n```sage\n\"\"\"\nParte 6 - Funções matriciais\n\"\"\"\n\n# Criando uma matriz\nA = matrix([[1, 2, 3], [4, 5, 6], [7, 8, 9]])\nB = matrix([[1, I], [-I, 2],[-2*I,1]])\n# Calculando o determinante da matriz\ndeterminante = A.det()\n\n# Calculando a transposta da matriz\ntransposta = A.transpose()\n\n# Calculando a matriz inversa\ninversa = A.inverse()\n\n# Calculando a conjugada da matriz\nconjugada = B.conjugate()\n\ndeterminante, transposta, inversa, conjugada\n```\n\n</details>","date":"2024-04-20T20:41:39.907Z"}],"sender_id":"57ec71b6-a18b-44c0-a581-818804af3b11"}
{"date":"2024-04-20T20:41:39.916Z","editing":{},"event":"chat","generating":false,"history":[{"author_id":"openai-gpt-3.5-turbo","content":"The error \"ZeroDivisionError: matrix must be nonsingular\" occurs because you are trying to calculate the inverse of a matrix that is singular (not invertible). \n\nYou can add a check before calculating the inverse to ensure the matrix is nonsingular. Here's an updated version of your code snippet:\n\n```sage\n\"\"\"\nParte 6 - Funções matriciais\n\"\"\"\n\n# Criando uma matriz\nA = matrix([[1, 2, 3], [4, 5, 6], [7, 8, 9]])\nB = matrix([[1, I], [-I, 2],[-2*I,1]])\n# Calculando o determinante da matriz\ndeterminante = A.det()\n\n# Calculando a transposta da matriz\ntransposta = A.transpose()\n\n# Check if A is nonsingular before calculating the inverse\nif A.is_singular():\n    inversa = \"Matrix A is singular and does not have an inverse.\"\nelse:\n    inversa = A.inverse()\n\n# Calculando a conjugada da matriz\nconjugada = B.conjugate()\n\ndeterminante, transposta, inversa, conjugada\n```","date":"2024-04-20T20:41:44.309Z"}],"reply_to":"2024-04-20T20:41:39.907Z","sender_id":"openai-gpt-3.5-turbo"}
{"date":"2024-04-20T20:55:07.804Z","editing":{},"event":"chat","history":[{"author_id":"57ec71b6-a18b-44c0-a581-818804af3b11","content":"<span class=\"user-mention\" account-id=openai-gpt-3.5-turbo >@GPT-3.5</span> Help me fix my code.\n\n<details><summary>Context</summary>\n\nI ran a cell in a Sage Worksheet.\n\nI received the following error:\n\n```sage\nError in lines 3-4\nTraceback (most recent call last):\n  File \"/cocalc/lib/python3.11/site-packages/smc_sagews/sage_server.py\", line 1245, in execute\n    compile(block + '\\n',\n  File \"<string>\", line 1\n    B = matrix([[Integer(1), I], [-I, Integer(2)],[-Integer(2)*I,Integer(1)]])\n                                                                              ^\nSyntaxError: multiple statements found while compiling a single statement\n\n```\n\nMy SageMath Worksheet contains:\n\n```sage\n\"\"\"\nParte 6 - Funções matriciais\n\"\"\"\n\n# Criando uma matriz\nA = matrix([[1, 2, 3], [4, 5, 6], [7, 8, 9]])\nB = matrix([[1, I], [-I, 2],[-2*I,1]])\n# Calculando o determinante da matriz\ndeterminante = A.det()\n\n\n# Calculando a transposta da matriz\ntransposta = A.transpose()\n\n# Calculando a matriz inversa\nif A.is_invertible(): #Se for por outra matriz que não seja \"A\", troque \"A\".is_invertible(): \n inversa = A.inverse()#Se for por outra matriz que não seja \"A\", troque \"A\".inverse() \nelse:\n inversa = 'Não tem inversa'\n\n# Calculando a conjugada da matriz\nconjugada = B.conjugate()\n\ndeterminante, transposta, inversa, conjugada\n```\n\n</details>","date":"2024-04-20T20:55:07.804Z"}],"sender_id":"57ec71b6-a18b-44c0-a581-818804af3b11"}
{"date":"2024-04-20T20:55:07.812Z","editing":{},"event":"chat","generating":false,"history":[{"author_id":"openai-gpt-3.5-turbo","content":"The error message indicates that there is an issue with the syntax when defining the matrix B due to multiple statements found while compiling a single statement. The problematic line is where you define matrix B:\n\nChange:\n```sage\nB = matrix([[1, I], [-I, 2],[-2*I,1]])\n```\nto:\n```sage\nB = matrix([[1, I], [-I, 2], [-2*I, 1]])\n```\nEnsure that each row in the matrix is separated by a comma.","date":"2024-04-20T20:55:10.601Z"}],"reply_to":"2024-04-20T20:55:07.804Z","sender_id":"openai-gpt-3.5-turbo"}
{"date":"2024-04-21T00:05:19.014Z","editing":{},"event":"chat","history":[{"author_id":"57ec71b6-a18b-44c0-a581-818804af3b11","content":"<span class=\"user-mention\" account-id=openai-gpt-3.5-turbo >@GPT-3.5</span> Help me fix my code.\n\n<details><summary>Context</summary>\n\nI ran a cell in a Sage Worksheet.\n\nI received the following error:\n\n```sage\nError in lines 11-11\nTraceback (most recent call last):\n  File \"/cocalc/lib/python3.11/site-packages/smc_sagews/sage_server.py\", line 1244, in execute\n    exec(\n  File \"\", line 1, in <module>\nAttributeError: 'tuple' object has no attribute 'solve_right'\n\n```\n\nMy SageMath Worksheet contains:\n\n```sage\n\"\"\"\nParte final - Sistemas lineares\n\n\"\"\"\n\n#Resolvendo sistemas lineares\n\nvar('x y z')\neq1 = 2*x + y - z == 1\neq2 = -x + y + z == 2\neq3 = x + 2*y - 3*z == 3\n\nsolucao = solve([eq1, eq2, eq3], [x,y,z])\n\nsolucao\n\n#Resolvendo o sistema linear por matriz\n\nvar('x y z')\nA = (3,3, [2,1,-1, 2,1,-1, 1,2,-3])\nvetor = vector([x,y,z])\nsolucao = A.solve_right(vetor)\n```\n\n</details>","date":"2024-04-21T00:05:19.014Z"}],"sender_id":"57ec71b6-a18b-44c0-a581-818804af3b11"}
{"date":"2024-04-21T00:05:19.030Z","editing":{},"event":"chat","generating":false,"history":[{"author_id":"openai-gpt-3.5-turbo","content":"The issue in your code is that you are trying to use the `solve_right()` method on a tuple `A`, which does not have this attribute. To fix this, convert the tuple `A` into a matrix and then use the `solve_right()` method. Here's how you can modify your code:\n\n```sage\n\"\"\"\nParte final - Sistemas lineares\n\n\"\"\"\n\n#Resolvendo sistemas lineares\n\nvar('x y z')\neq1 = 2*x + y - z == 1\neq2 = -x + y + z == 2\neq3 = x + 2*y - 3*z == 3\n\nsolucao = solve([eq1, eq2, eq3], [x,y,z])\n\nsolucao\n\n#Resolvendo o sistema linear por matriz\n\nvar('x y z')\nA = matrix([[2,1,-1], [2,1,-1], [1,2,-3]])\nvetor = vector([x,y,z])\nsolucao = A.solve_right(vetor)\n```\n\nThis modification will resolve the AttributeError you encountered.","date":"2024-04-21T00:05:23.700Z"}],"reply_to":"2024-04-21T00:05:19.014Z","sender_id":"openai-gpt-3.5-turbo"}
{"date":"2024-04-21T00:06:44.216Z","editing":{},"event":"chat","history":[{"author_id":"57ec71b6-a18b-44c0-a581-818804af3b11","content":"<span class=\"user-mention\" account-id=openai-gpt-3.5-turbo >@GPT-3.5</span> Help me fix my code.\n\n<details><summary>Context</summary>\n\nI ran a cell in a Sage Worksheet.\n\nI received the following error:\n\n```sage\nError in lines 12-12\nTraceback (most recent call last):\n  File \"sage/matrix/matrix2.pyx\", line 942, in sage.matrix.matrix2.Matrix.solve_right\n    X = self._solve_right_nonsingular_square(C, check_rank=True)\n  File \"sage/matrix/matrix2.pyx\", line 988, in sage.matrix.matrix2.Matrix._solve_right_nonsingular_square\n    raise NotFullRankError\nsage.matrix.matrix2.NotFullRankError\n\nDuring handling of the above exception, another exception occurred:\n\nTraceback (most recent call last):\n  File \"/cocalc/lib/python3.11/site-packages/smc_sagews/sage_server.py\", line 1244, in execute\n    exec(\n  File \"\", line 1, in <module>\n  File \"sage/matrix/matrix2.pyx\", line 944, in sage.matrix.matrix2.Matrix.solve_right\n    X = self._solve_right_general(C, check=check)\n  File \"sage/matrix/matrix2.pyx\", line 1062, in sage.matrix.matrix2.Matrix._solve_right_general\n    raise ValueError(\"matrix equation has no solutions\")\nValueError: matrix equation has no solutions\n\n```\n\nMy SageMath Worksheet contains:\n\n```sage\n\"\"\"\nParte final - Sistemas lineares\n\n\"\"\"\n\n#Resolvendo sistemas lineares\n\n\"\"\"\nParte final - Sistemas lineares\n\n\"\"\"\n\n#Resolvendo sistemas lineares\n\nvar('x y z')\neq1 = 2*x + y - z == 1\neq2 = -x + y + z == 2\neq3 = x + 2*y - 3*z == 3\n\nsolucao = solve([eq1, eq2, eq3], [x,y,z])\n\nsolucao\n\n#Resolvendo o sistema linear por matriz\n\nvar('x y z')\nA = matrix([[2,1,-1], [2,1,-1], [1,2,-3]])\nvetor = vector([x,y,z])\nsolucao = A.solve_right(vetor)\n\nsolucao\n```\n\n</details>","date":"2024-04-21T00:06:44.216Z"}],"sender_id":"57ec71b6-a18b-44c0-a581-818804af3b11"}
{"date":"2024-04-21T00:06:44.229Z","editing":{},"event":"chat","generating":false,"history":[{"author_id":"openai-gpt-3.5-turbo","content":"The error you are encountering is due to the fact that the matrix A you are trying to solve in the second part of your worksheet is not full rank, meaning it doesn't have a unique solution. This is likely caused by a mistake in defining the coefficients of the linear equations.\n\nTo fix the code, make sure that the matrix A is properly defined with the correct coefficients of the equations. Check that the coefficients in the matrix match the coefficients in the linear equations.","date":"2024-04-21T00:06:46.426Z"}],"reply_to":"2024-04-21T00:06:44.216Z","sender_id":"openai-gpt-3.5-turbo"}
{"date":"2024-04-21T00:10:24.651Z","editing":{},"event":"chat","history":[{"author_id":"57ec71b6-a18b-44c0-a581-818804af3b11","content":"<span class=\"user-mention\" account-id=openai-gpt-3.5-turbo >@GPT-3.5</span> Help me fix my code.\n\n<details><summary>Context</summary>\n\nI ran a cell in a Sage Worksheet.\n\nI received the following error:\n\n```sage\n\n\n*** WARNING: Code contains possible implicit multiplication    ***\n*** Check if any of [ 4z ] need a \"*\" sign for multiplication, e.g. 5x should be 5*x ! ***\n\nError in lines 5-5\nTraceback (most recent call last):\n  File \"/cocalc/lib/python3.11/site-packages/smc_sagews/sage_server.py\", line 1245, in execute\n    compile(block + '\\n',\n  File \"<string>\", line 1\n    eq2 = Integer(2)*x + y + 4z == Integer(2)\n                             ^\nSyntaxError: invalid decimal literal\n\n```\n\nMy SageMath Worksheet contains:\n\n```sage\n\"\"\"\nParte final - Sistemas lineares\n\n\"\"\"\n\n#Resolvendo sistemas lineares\n\n\"\"\"\nParte final - Sistemas lineares\n\n\"\"\"\n\n#Resolvendo sistemas lineares\n\nvar('x y z')\neq1 = 2*x + y - z == 1\neq2 = 2*x + y + 4z == 2\neq3 = x + 2*y - 5*z == 3\n\nsolucao = solve([eq1, eq2, eq3], [x,y,z])\n\nsolucao\n\n#Resolvendo o sistema linear por matriz\n\nvar('x y z')\nA = matrix([[2,1,-1], [2,1,4], [1,2,-5]])\nvetor = vector([x,y,z])\nsolucao = A.solve_right(0)\n\nsolucao\n```\n\n</details>","date":"2024-04-21T00:10:24.651Z"}],"sender_id":"57ec71b6-a18b-44c0-a581-818804af3b11"}
{"date":"2024-04-21T00:10:24.665Z","editing":{},"event":"chat","generating":false,"history":[{"author_id":"openai-gpt-3.5-turbo","content":"The error in your code is due to the expression `4z` in the equation `eq2`. To fix it, you need to add a `*` between `4` and `z`, making it `4*z` for correct multiplication.\n\nCorrected code snippet:\n\n```sage\nvar('x y z')\neq1 = 2*x + y - z == 1\neq2 = 2*x + y + 4*z == 2\neq3 = x + 2*y - 5*z == 3\n\nsolucao = solve([eq1, eq2, eq3], [x,y,z])\n\nsolucao\n```","date":"2024-04-21T00:10:27.148Z"}],"reply_to":"2024-04-21T00:10:24.651Z","sender_id":"openai-gpt-3.5-turbo"}
{"date":"2024-04-21T00:16:07.502Z","editing":{},"event":"chat","history":[{"author_id":"57ec71b6-a18b-44c0-a581-818804af3b11","content":"<span class=\"user-mention\" account-id=openai-gpt-3.5-turbo >@GPT-3.5</span> Help me fix my code.\n\n<details><summary>Context</summary>\n\nI ran a cell in a Sage Worksheet.\n\nI received the following error:\n\n```sage\nError in lines 8-8\nTraceback (most recent call last):\n  File \"/cocalc/lib/python3.11/site-packages/smc_sagews/sage_server.py\", line 1245, in execute\n    compile(block + '\\n',\n  File \"<string>\", line 1\n    show(solucao[Integer(0)]) show(solucao[Integer(1)]) show(solucao[Integer(2)])\n                              ^^^^\nSyntaxError: invalid syntax\n\n```\n\nMy SageMath Worksheet contains:\n\n```sage\n\"\"\"\nParte final - Sistemas lineares\n\n\"\"\"\n\n#Resolvendo sistemas lineares\n\n\"\"\"\nParte final - Sistemas lineares\n\n\"\"\"\n\n#Resolvendo sistemas lineares\n\nvar('x y z');\neq1 = 2*x + y - z == 1\neq2 = 2*x + y + 4*z == 2\neq3 = x + 2*y - 5*z == 3\n\nsolucao = solve([eq1, eq2, eq3], [x,y,z])\n\nshow(solucao[0]) show(solucao[1]) show(solucao[2])\n\n#Resolvendo o sistema linear por matriz\n\nvar('x y z');\nA = matrix([[2,1,-1], [2,1,4], [1,2,-5]])\nvetor = vector([1,2,3])\nsolucao = A.solve_right(vetor)\n\nshow(solucao[0]) show(solucao[1]) show(solucao[2])\n```\n\n</details>","date":"2024-04-21T00:16:07.502Z"}],"sender_id":"57ec71b6-a18b-44c0-a581-818804af3b11"}
{"date":"2024-04-21T00:16:07.518Z","editing":{},"event":"chat","generating":false,"history":[{"author_id":"openai-gpt-3.5-turbo","content":"The issue in your code is in the line that tries to display the solutions. You need to separate the `show` functions with commas or semicolons instead of spaces. Here is the corrected part of your code:\n\n```sage\nshow(solucao[0]), show(solucao[1]), show(solucao[2])\n```","date":"2024-04-21T00:16:09.266Z"}],"reply_to":"2024-04-21T00:16:07.502Z","sender_id":"openai-gpt-3.5-turbo"}
{"date":"2024-04-21T00:17:01.933Z","editing":{},"event":"chat","history":[{"author_id":"57ec71b6-a18b-44c0-a581-818804af3b11","content":"<span class=\"user-mention\" account-id=openai-gpt-3.5-turbo >@GPT-3.5</span> Help me fix my code.\n\n<details><summary>Context</summary>\n\nI ran a cell in a Sage Worksheet.\n\nI received the following error:\n\n```sage\nError in lines 8-8\nTraceback (most recent call last):\n  File \"/cocalc/lib/python3.11/site-packages/smc_sagews/sage_server.py\", line 1244, in execute\n    exec(\n  File \"\", line 1, in <module>\n  File \"/ext/sage/10.3/src/sage/structure/sequence.py\", line 527, in __getitem__\n    return list.__getitem__(self,n)\n           ^^^^^^^^^^^^^^^^^^^^^^^^\nIndexError: list index out of range\n\n```\n\nMy SageMath Worksheet contains:\n\n```sage\n\"\"\"\nParte final - Sistemas lineares\n\n\"\"\"\n\n#Resolvendo sistemas lineares\n\n\"\"\"\nParte final - Sistemas lineares\n\n\"\"\"\n\n#Resolvendo sistemas lineares\n\nvar('x y z');\neq1 = 2*x + y - z == 1\neq2 = 2*x + y + 4*z == 2\neq3 = x + 2*y - 5*z == 3\n\nsolucao = solve([eq1, eq2, eq3], [x,y,z])\n\nshow(solucao[0]), show(solucao[1]), show(solucao[2])\n\n#Resolvendo o sistema linear por matriz\n\nvar('x y z');\nA = matrix([[2,1,-1], [2,1,4], [1,2,-5]])\nvetor = vector([1,2,3])\nsolucao = A.solve_right(vetor)\n\nshow(solucao[0]), show(solucao[1]), show(solucao[2])\n```\n\n</details>","date":"2024-04-21T00:17:01.933Z"}],"sender_id":"57ec71b6-a18b-44c0-a581-818804af3b11"}
{"date":"2024-04-21T00:17:01.960Z","editing":{},"event":"chat","generating":false,"history":[{"author_id":"openai-gpt-3.5-turbo","content":"The error in your code is due to trying to access an index in the solution tuple that is out of range. This likely occurs because the solve function did not find a solution and returned an empty list. To avoid this error, you can check if the solution list is not empty before accessing its elements.","date":"2024-04-21T00:17:03.696Z"}],"reply_to":"2024-04-21T00:17:01.933Z","sender_id":"openai-gpt-3.5-turbo"}
{"date":"2024-04-21T00:17:53.310Z","editing":{},"event":"chat","history":[{"author_id":"57ec71b6-a18b-44c0-a581-818804af3b11","content":"<span class=\"user-mention\" account-id=openai-gpt-3.5-turbo >@GPT-3.5</span> Help me fix my code.\n\n<details><summary>Context</summary>\n\nI ran a cell in a Sage Worksheet.\n\nI received the following error:\n\n```sage\nError in lines 8-8\nTraceback (most recent call last):\n  File \"/cocalc/lib/python3.11/site-packages/smc_sagews/sage_server.py\", line 1244, in execute\n    exec(\n  File \"\", line 1, in <module>\n  File \"/ext/sage/10.3/src/sage/structure/sequence.py\", line 527, in __getitem__\n    return list.__getitem__(self,n)\n           ^^^^^^^^^^^^^^^^^^^^^^^^\nIndexError: list index out of range\n\n```\n\nMy SageMath Worksheet contains:\n\n```sage\n\"\"\"\nParte final - Sistemas lineares\n\n\"\"\"\n\n#Resolvendo sistemas lineares\n\n\"\"\"\nParte final - Sistemas lineares\n\n\"\"\"\n\n#Resolvendo sistemas lineares\n\nvar('x y z');\neq1 = 2*x + y - z == 1\neq2 = 2*x + y + 4*z == 2\neq3 = x + 2*y - 5*z == 3\n\nsolucao1 = solve([eq1, eq2, eq3], [x,y,z])\n\nshow(solucao1[0]), show(solucao1[1]), show(solucao1[2])\n\n#Resolvendo o sistema linear por matriz\n\nvar('x y z');\nA = matrix([[2,1,-1], [2,1,4], [1,2,-5]])\nvetor = vector([1,2,3])\nsolucao2 = A.solve_right(vetor)\n\nshow(solucao2[0]), show(solucao2[1]), show(solucao2[2])\n```\n\n</details>","date":"2024-04-21T00:17:53.310Z"}],"sender_id":"57ec71b6-a18b-44c0-a581-818804af3b11"}
{"date":"2024-04-21T00:17:53.335Z","editing":{},"event":"chat","generating":false,"history":[{"author_id":"openai-gpt-3.5-turbo","content":"The error \"IndexError: list index out of range\" in your SageMath code is likely due to trying to access an index in a list that is out of bounds. \n\nIn your code, the issue may be related to the solutions obtained from solving the system of linear equations. Check if the solutions stored in `solucao1` and `solucao2` lists are empty or have fewer elements. You should verify the correctness of the solutions calculated for the system of equations provided. \n\nIn addition, make sure to define all symbolic variables (such as 'x', 'y', 'z') at the beginning of the code snippet and avoid redundant code repetitions in the SageMath Worksheet.","date":"2024-04-21T00:17:56.141Z"}],"reply_to":"2024-04-21T00:17:53.310Z","sender_id":"openai-gpt-3.5-turbo"}
{"date":"2024-04-21T00:23:45.758Z","editing":{},"event":"chat","history":[{"author_id":"57ec71b6-a18b-44c0-a581-818804af3b11","content":"<span class=\"user-mention\" account-id=openai-gpt-3.5-turbo >@GPT-3.5</span> Help me fix my code.\n\n<details><summary>Context</summary>\n\nI ran a cell in a Sage Worksheet.\n\nI received the following error:\n\n```sage\nError in lines 13-13\nTraceback (most recent call last):\n  File \"/cocalc/lib/python3.11/site-packages/smc_sagews/sage_server.py\", line 1244, in execute\n    exec(\n  File \"\", line 1, in <module>\nNameError: name 'a' is not defined\n\n```\n\nMy SageMath Worksheet contains:\n\n```sage\n\"\"\"\nParte final - Sistemas lineares\n\n\"\"\"\n\n#Resolvendo sistemas lineares\n\n\"\"\"\nParte final - Sistemas lineares\n\n\"\"\"\n\n#Resolvendo sistemas lineares\n\nvar('x y z')\neq1 = 2*x + y - z == 1\neq2 = 2*x + y + 4*z == 2\neq3 = x + 2*y - 5*z == 3\n\nsolucao = solve([eq1, eq2, eq3], [x,y,z])\n\nsolucao\n\n#Resolvendo o sistema linear por matriz\n\nvar('x y z')\nA = matrix([[2,1,-1], [2,1,4], [1,2,-5]])\nvetor = vector([1,2,3])\nsolucao = A.solve_right(vetor)\nsol = solve([[2,1,-1], [2,1,4], [1,2,-5]], a,b,c)\nshow(sol[0]) \nshow(sol[1])\nsolucao\n```\n\n</details>","date":"2024-04-21T00:23:45.758Z"}],"sender_id":"57ec71b6-a18b-44c0-a581-818804af3b11"}
{"date":"2024-04-21T00:23:45.776Z","editing":{},"event":"chat","generating":false,"history":[{"author_id":"openai-gpt-3.5-turbo","content":"In your code, the variable 'a' is not defined. To fix this error, you can replace 'sol = solve([[2,1,-1], [2,1,4], [1,2,-5]], a,b,c)' with 'sol = solve([eq1, eq2, eq3], x, y, z)'. This will correctly solve the system of linear equations using the variables x, y, and z that were defined earlier.","date":"2024-04-21T00:23:47.831Z"}],"reply_to":"2024-04-21T00:23:45.758Z","sender_id":"openai-gpt-3.5-turbo"}
{"date":"2024-04-21T00:24:36.067Z","editing":{},"event":"chat","history":[{"author_id":"57ec71b6-a18b-44c0-a581-818804af3b11","content":"<span class=\"user-mention\" account-id=openai-gpt-3.5-turbo >@GPT-3.5</span> Help me fix my code.\n\n<details><summary>Context</summary>\n\nI ran a cell in a Sage Worksheet.\n\nI received the following error:\n\n```sage\nError in lines 8-8\nTraceback (most recent call last):\n  File \"/cocalc/lib/python3.11/site-packages/smc_sagews/sage_server.py\", line 1244, in execute\n    exec(\n  File \"\", line 1, in <module>\nNameError: name 'a' is not defined\n\n```\n\nMy SageMath Worksheet contains:\n\n```sage\n\"\"\"\nParte final - Sistemas lineares\n\n\"\"\"\n\n#Resolvendo sistemas lineares\n\n\"\"\"\nParte final - Sistemas lineares\n\n\"\"\"\n\n#Resolvendo sistemas lineares\n\nvar('x y z')\neq1 = 2*x + y - z == 1\neq2 = 2*x + y + 4*z == 2\neq3 = x + 2*y - 5*z == 3\n\nsolucao = solve([eq1, eq2, eq3], [x,y,z])\nsol = solve([[2,1,-1], [2,1,4], [1,2,-5]], a,b,c)\nshow(sol[0]) \nshow(sol[1])\n\nsolucao\n\n#Resolvendo o sistema linear por matriz\n\nvar('x y z')\nA = matrix([[2,1,-1], [2,1,4], [1,2,-5]])\nvetor = vector([1,2,3])\nsolucao = A.solve_right(vetor)\nsolucao\n```\n\n</details>","date":"2024-04-21T00:24:36.067Z"}],"sender_id":"57ec71b6-a18b-44c0-a581-818804af3b11"}
{"date":"2024-04-21T00:24:36.078Z","editing":{},"event":"chat","generating":false,"history":[{"author_id":"openai-gpt-3.5-turbo","content":"The error is in line 17 where you are trying to solve the system of equations using the variables a, b, c, which are not defined. You should use x, y, z instead.\n\nReplace:\n```sage\nsol = solve([[2,1,-1], [2,1,4], [1,2,-5]], a,b,c)\n```\n\nwith:\n```sage\nsol = solve([eq1,eq2,eq3], x,y,z)\n```","date":"2024-04-21T00:24:38.669Z"}],"reply_to":"2024-04-21T00:24:36.067Z","sender_id":"openai-gpt-3.5-turbo"}
{"date":"2024-04-21T00:25:09.701Z","editing":{},"event":"chat","history":[{"author_id":"57ec71b6-a18b-44c0-a581-818804af3b11","content":"<span class=\"user-mention\" account-id=openai-gpt-3.5-turbo >@GPT-3.5</span> Help me fix my code.\n\n<details><summary>Context</summary>\n\nI ran a cell in a Sage Worksheet.\n\nI received the following error:\n\n```sage\nError in lines 9-9\nTraceback (most recent call last):\n  File \"/cocalc/lib/python3.11/site-packages/smc_sagews/sage_server.py\", line 1244, in execute\n    exec(\n  File \"\", line 1, in <module>\nNameError: name 'sol' is not defined\n\n```\n\nMy SageMath Worksheet contains:\n\n```sage\n\"\"\"\nParte final - Sistemas lineares\n\n\"\"\"\n\n#Resolvendo sistemas lineares\n\n\"\"\"\nParte final - Sistemas lineares\n\n\"\"\"\n\n#Resolvendo sistemas lineares\n\nvar('x y z')\neq1 = 2*x + y - z == 1\neq2 = 2*x + y + 4*z == 2\neq3 = x + 2*y - 5*z == 3\n\nsolucao = solve([eq1, eq2, eq3], [x,y,z])\nsolve([eq1,eq2,eq3], x,y,z)\nshow(sol[0]) \nshow(sol[1])\n\nsolucao\n\n#Resolvendo o sistema linear por matriz\n\nvar('x y z')\nA = matrix([[2,1,-1], [2,1,4], [1,2,-5]])\nvetor = vector([1,2,3])\nsolucao = A.solve_right(vetor)\nsolucao\n```\n\n</details>","date":"2024-04-21T00:25:09.701Z"}],"sender_id":"57ec71b6-a18b-44c0-a581-818804af3b11"}
{"date":"2024-04-21T00:25:09.732Z","editing":{},"event":"chat","generating":false,"history":[{"author_id":"openai-gpt-3.5-turbo","content":"The error in line 9 (`NameError: name 'sol' is not defined`) is because you attempted to show `sol[0]` and `sol[1]`, but you defined the variable as `solucao`. To fix this, change `sol[0]` and `sol[1]` to `solucao[0]` and `solucao[1]` respectively.","date":"2024-04-21T00:25:11.751Z"}],"reply_to":"2024-04-21T00:25:09.701Z","sender_id":"openai-gpt-3.5-turbo"}
{"date":"2024-04-21T00:25:29.122Z","editing":{},"event":"chat","history":[{"author_id":"57ec71b6-a18b-44c0-a581-818804af3b11","content":"<span class=\"user-mention\" account-id=openai-gpt-3.5-turbo >@GPT-3.5</span> Help me fix my code.\n\n<details><summary>Context</summary>\n\nI ran a cell in a Sage Worksheet.\n\nI received the following error:\n\n```sage\nError in lines 10-10\nTraceback (most recent call last):\n  File \"/cocalc/lib/python3.11/site-packages/smc_sagews/sage_server.py\", line 1244, in execute\n    exec(\n  File \"\", line 1, in <module>\n  File \"/ext/sage/10.3/src/sage/structure/sequence.py\", line 527, in __getitem__\n    return list.__getitem__(self,n)\n           ^^^^^^^^^^^^^^^^^^^^^^^^\nIndexError: list index out of range\n\n```\n\nMy SageMath Worksheet contains:\n\n```sage\n\"\"\"\nParte final - Sistemas lineares\n\n\"\"\"\n\n#Resolvendo sistemas lineares\n\n\"\"\"\nParte final - Sistemas lineares\n\n\"\"\"\n\n#Resolvendo sistemas lineares\n\nvar('x y z')\neq1 = 2*x + y - z == 1\neq2 = 2*x + y + 4*z == 2\neq3 = x + 2*y - 5*z == 3\n\nsolucao = solve([eq1, eq2, eq3], [x,y,z])\nsol= solve([eq1,eq2,eq3], x,y,z)\nshow(sol[0]) \nshow(sol[1])\n\nsolucao\n\n#Resolvendo o sistema linear por matriz\n\nvar('x y z')\nA = matrix([[2,1,-1], [2,1,4], [1,2,-5]])\nvetor = vector([1,2,3])\nsolucao = A.solve_right(vetor)\nsolucao\n```\n\n</details>","date":"2024-04-21T00:25:29.122Z"}],"sender_id":"57ec71b6-a18b-44c0-a581-818804af3b11"}
{"date":"2024-04-21T00:25:29.147Z","editing":{},"event":"chat","generating":false,"history":[{"author_id":"openai-gpt-3.5-turbo","content":"The error \"IndexError: list index out of range\" in SageMath typically occurs when trying to access an index that is outside the range of a list or sequence.\n\nIn your code snippet, you are attempting to access indices of the solutions `sol[0]` and `sol[1]` without checking if they exist. Ensure that the solutions are not empty before accessing them.\n\nHere is a revised version of your code snippet:\n\n```sage\nvar('x y z')\neq1 = 2*x + y - z == 1\neq2 = 2*x + y + 4*z == 2\neq3 = x + 2*y - 5*z == 3\n\nsol = solve([eq1, eq2, eq3], x, y, z)\n\nif sol:\n    show(sol[0])\n    show(sol[1])\n\nA = matrix([[2, 1, -1], [2, 1, 4], [1, 2, -5]])\nb = vector([1, 2, 3])\nsol_matrix = A.solve_right(b)\nsol_matrix\n```\n\nThis revision includes a check to ensure that the solutions exist before attempting to display or access them.","date":"2024-04-21T00:25:32.857Z"}],"reply_to":"2024-04-21T00:25:29.122Z","sender_id":"openai-gpt-3.5-turbo"}
{"date":"2024-04-21T00:26:38.124Z","editing":{},"event":"chat","history":[{"author_id":"57ec71b6-a18b-44c0-a581-818804af3b11","content":"<span class=\"user-mention\" account-id=openai-gpt-3.5-turbo >@GPT-3.5</span> Help me fix my code.\n\n<details><summary>Context</summary>\n\nI ran a cell in a Sage Worksheet.\n\nI received the following error:\n\n```sage\nError in lines 10-10\nTraceback (most recent call last):\n  File \"/cocalc/lib/python3.11/site-packages/smc_sagews/sage_server.py\", line 1244, in execute\n    exec(\n  File \"\", line 1, in <module>\n  File \"/ext/sage/10.3/src/sage/structure/sequence.py\", line 527, in __getitem__\n    return list.__getitem__(self,n)\n           ^^^^^^^^^^^^^^^^^^^^^^^^\nIndexError: list index out of range\n\n```\n\nMy SageMath Worksheet contains:\n\n```sage\n\"\"\"\nParte final - Sistemas lineares\n\n\"\"\"\n\n#Resolvendo sistemas lineares\n\n\"\"\"\nParte final - Sistemas lineares\n\n\"\"\"\n\n#Resolvendo sistemas lineares\n\nvar('x y z')\neq1 = 2*x + y - z == 1\neq2 = 2*x + y + 4*z == 2\neq3 = x + 2*y - 5*z == 3\n\nsolucao = solve([eq1, eq2, eq3], [x,y,z])\nsol= solve([eq1,eq2,eq3], x,y,z)\nshow(sol[0]) \nshow(sol[1])\n\nif sol:\n    show(sol[0])\n    show(sol[1])\nelse:\n    show(solucao)\n\n#Resolvendo o sistema linear por matriz\n\nvar('x y z')\nA = matrix([[2,1,-1], [2,1,4], [1,2,-5]])\nvetor = vector([1,2,3])\nsolucao = A.solve_right(vetor)\nsolucao\n```\n\n</details>","date":"2024-04-21T00:26:38.124Z"}],"sender_id":"57ec71b6-a18b-44c0-a581-818804af3b11"}
{"date":"2024-04-21T00:26:38.146Z","editing":{},"event":"chat","generating":false,"history":[{"author_id":"openai-gpt-3.5-turbo","content":"The error \"IndexError: list index out of range\" occurs because you are trying to access elements that do not exist in the list `sol`. To fix this, you should check if `sol` is not empty before trying to access its elements. Here's the corrected part of your code:\n\n```sage\nif sol:\n    show(sol[0])\n    show(sol[1])\n```\n\nBy adding this check before accessing elements of `sol`, you can prevent the \"list index out of range\" error.","date":"2024-04-21T00:26:40.201Z"}],"reply_to":"2024-04-21T00:26:38.124Z","sender_id":"openai-gpt-3.5-turbo"}
{"date":"2024-04-21T00:27:15.313Z","editing":{},"event":"chat","history":[{"author_id":"57ec71b6-a18b-44c0-a581-818804af3b11","content":"<span class=\"user-mention\" account-id=openai-gpt-3.5-turbo >@GPT-3.5</span> Help me fix my code.\n\n<details><summary>Context</summary>\n\nI ran a cell in a Sage Worksheet.\n\nI received the following error:\n\n```sage\nError in lines 9-13\nTraceback (most recent call last):\n  File \"/cocalc/lib/python3.11/site-packages/smc_sagews/sage_server.py\", line 1244, in execute\n    exec(\n  File \"\", line 3, in <module>\n  File \"/ext/sage/10.3/src/sage/structure/sequence.py\", line 527, in __getitem__\n    return list.__getitem__(self,n)\n           ^^^^^^^^^^^^^^^^^^^^^^^^\nIndexError: list index out of range\n\n```\n\nMy SageMath Worksheet contains:\n\n```sage\n\"\"\"\nParte final - Sistemas lineares\n\n\"\"\"\n\n#Resolvendo sistemas lineares\n\n\"\"\"\nParte final - Sistemas lineares\n\n\"\"\"\n\n#Resolvendo sistemas lineares\n\nvar('x y z')\neq1 = 2*x + y - z == 1\neq2 = 2*x + y + 4*z == 2\neq3 = x + 2*y - 5*z == 3\n\nsolucao = solve([eq1, eq2, eq3], [x,y,z])\nsol= solve([eq1,eq2,eq3], x,y,z)\n\n\nif sol:\n    show(sol[0])\n    show(sol[1])\nelse:\n    show(solucao)\n\n#Resolvendo o sistema linear por matriz\n\nvar('x y z')\nA = matrix([[2,1,-1], [2,1,4], [1,2,-5]])\nvetor = vector([1,2,3])\nsolucao = A.solve_right(vetor)\nsolucao\n```\n\n</details>","date":"2024-04-21T00:27:15.313Z"}],"sender_id":"57ec71b6-a18b-44c0-a581-818804af3b11"}
{"date":"2024-04-21T00:27:15.328Z","editing":{},"event":"chat","generating":false,"history":[{"author_id":"openai-gpt-3.5-turbo","content":"The error in your code is occurring because the list index is out of range when trying to access `sol[0]` and `sol[1]`. To fix this issue, you can check if `sol` contains valid solutions before accessing its elements. Here is an updated version of your code:\n\n```sage\nvar('x y z')\neq1 = 2*x + y - z == 1\neq2 = 2*x + y + 4*z == 2\neq3 = x + 2*y - 5*z == 3\n\nsol = solve([eq1, eq2, eq3], x, y, z)\n\nif sol:\n    show(sol[x])\n    show(sol[y])\nelse:\n    show(sol)\n\n# Resolving the linear system using matrices\n\nvar('x y z')\nA = matrix([[2, 1, -1], [2, 1, 4], [1, 2, -5]])\nvector = vector([1, 2, 3])\nsolution = A.solve_right(vector)\nsolution\n``` \n\nMake sure to run this updated code in your Sage Worksheet to avoid the list index out of range error.","date":"2024-04-21T00:27:18.912Z"}],"reply_to":"2024-04-21T00:27:15.313Z","sender_id":"openai-gpt-3.5-turbo"}
{"date":"2024-04-21T00:28:49.563Z","editing":{},"event":"chat","history":[{"author_id":"57ec71b6-a18b-44c0-a581-818804af3b11","content":"<span class=\"user-mention\" account-id=openai-gpt-3.5-turbo >@GPT-3.5</span> Help me fix my code.\n\n<details><summary>Context</summary>\n\nI ran a cell in a Sage Worksheet.\n\nI received the following error:\n\n```sage\nError in lines 9-13\nTraceback (most recent call last):\n  File \"sage/symbolic/expression.pyx\", line 1505, in sage.symbolic.expression.Expression._integer_\n    n = self.pyobject()\n  File \"sage/symbolic/expression.pyx\", line 765, in sage.symbolic.expression.Expression.pyobject\n    raise TypeError(\"self must be a numeric expression\")\nTypeError: self must be a numeric expression\n\nDuring handling of the above exception, another exception occurred:\n\nTraceback (most recent call last):\n  File \"/cocalc/lib/python3.11/site-packages/smc_sagews/sage_server.py\", line 1244, in execute\n    exec(\n  File \"\", line 2, in <module>\n  File \"/ext/sage/10.3/src/sage/structure/sequence.py\", line 527, in __getitem__\n    return list.__getitem__(self,n)\n           ^^^^^^^^^^^^^^^^^^^^^^^^\n  File \"sage/symbolic/expression.pyx\", line 6482, in sage.symbolic.expression.Expression.__index__\n    return int(self._integer_())\n  File \"sage/symbolic/expression.pyx\", line 1507, in sage.symbolic.expression.Expression._integer_\n    raise TypeError(\"unable to convert %r to an integer\" % self)\nTypeError: unable to convert x to an integer\n\n```\n\nMy SageMath Worksheet contains:\n\n```sage\n\"\"\"\nParte final - Sistemas lineares\n\n\"\"\"\n\n#Resolvendo sistemas lineares\n\n\"\"\"\nParte final - Sistemas lineares\n\n\"\"\"\n\n#Resolvendo sistemas lineares\n\nvar('x y z')\neq1 = 2*x + y - z == 1\neq2 = 2*x + y + 4*z == 2\neq3 = x + 2*y - 5*z == 3\n\nsolucao = solve([eq1, eq2, eq3], [x,y,z])\nsol= solve([eq1,eq2,eq3], x,y,z)\n\nif len(solucao) > 1:  # Verifica se há mais de uma solução\n    show(solucao[0][x])\n    show(solucao[0][y])\n    show(solucao[1][x])\n    show(solucao[1][y])\nelse:\n    show(solucao)\n\n#Resolvendo o sistema linear por matriz\n\nvar('x y z')\nA = matrix([[2,1,-1], [2,1,4], [1,2,-5]])\nvetor = vector([1,2,3])\nsolucao = A.solve_right(vetor)\nsolucao\n```\n\n</details>","date":"2024-04-21T00:28:49.563Z"}],"sender_id":"57ec71b6-a18b-44c0-a581-818804af3b11"}
{"date":"2024-04-21T00:28:49.584Z","editing":{"57ec71b6-a18b-44c0-a581-818804af3b11":"FUTURE"},"event":"chat","generating":false,"history":[{"author_id":"openai-gpt-3.5-turbo","content":"The error you are encountering seems to be related to trying to convert a symbolic expression to an integer. \n\nIn your code, there are two instances where you define the same variables within the same scope. This might be causing conflicts. Remove one of the variable declarations for x, y, z.\n\nAdditionally, check the solve method syntax. Ensure that the syntax for solving the system of equations is correct.\n\nYou may also want to check if the content inside the `if` statement is handling the solutions correctly when there is only one solution.\n\n```\nvar('x y z')\neq1 = 2*x + y - z == 1\neq2 = 2*x + y + 4*z == 2\neq3 = x + 2*y - 5*z == 3\n\nsolucao = solve([eq1, eq2, eq3], [x,y,z])\n\nif len(solucao) > 1:  \n    show(solucao[0][x])\n    show(solucao[0][y])\n    show(solucao[1][x])\n    show(solucao[1][y])\nelse:\n    show(solucao)\n\n#Resolvendo o sistema linear por matriz\n\nA = matrix([[2,1,-1], [2,1,4], [1,2,-5]])\nvetor = vector([1,2,3])\nsolucao = A.solve_right(vetor)\nsolucao\n```","date":"2024-04-21T00:28:56.208Z"}],"reply_to":"2024-04-21T00:28:49.563Z","sender_id":"openai-gpt-3.5-turbo"}
{"date":"2024-04-21T00:30:09.160Z","editing":{},"event":"chat","history":[{"author_id":"57ec71b6-a18b-44c0-a581-818804af3b11","content":"<span class=\"user-mention\" account-id=openai-gpt-3.5-turbo >@GPT-3.5</span> Help me fix my code.\n\n<details><summary>Context</summary>\n\nI ran a cell in a Sage Worksheet.\n\nI received the following error:\n\n```sage\nError in lines 9-13\nTraceback (most recent call last):\n  File \"sage/symbolic/expression.pyx\", line 1505, in sage.symbolic.expression.Expression._integer_\n    n = self.pyobject()\n  File \"sage/symbolic/expression.pyx\", line 765, in sage.symbolic.expression.Expression.pyobject\n    raise TypeError(\"self must be a numeric expression\")\nTypeError: self must be a numeric expression\n\nDuring handling of the above exception, another exception occurred:\n\nTraceback (most recent call last):\n  File \"/cocalc/lib/python3.11/site-packages/smc_sagews/sage_server.py\", line 1244, in execute\n    exec(\n  File \"\", line 2, in <module>\n  File \"/ext/sage/10.3/src/sage/structure/sequence.py\", line 527, in __getitem__\n    return list.__getitem__(self,n)\n           ^^^^^^^^^^^^^^^^^^^^^^^^\n  File \"sage/symbolic/expression.pyx\", line 6482, in sage.symbolic.expression.Expression.__index__\n    return int(self._integer_())\n  File \"sage/symbolic/expression.pyx\", line 1507, in sage.symbolic.expression.Expression._integer_\n    raise TypeError(\"unable to convert %r to an integer\" % self)\nTypeError: unable to convert x to an integer\n\n```\n\nMy SageMath Worksheet contains:\n\n```sage\n\"\"\"\nParte final - Sistemas lineares\n\n\"\"\"\n\n#Resolvendo sistemas lineares\n\n\"\"\"\nParte final - Sistemas lineares\n\n\"\"\"\n\n#Resolvendo sistemas lineares\n\nvar('x y z')\neq1 = 2*x + y - z == 1\neq2 = 2*x + y + 4*z == 2\neq3 = x + 2*y - 5*z == 3\n\nsolucao = solve([eq1, eq2, eq3], [x,y,z])\nsol= solve([eq1,eq2,eq3], x,y,z)\nshow(sol)\n\n#Resolvendo o sistema linear por matriz\n\nvar('x y z')\nA = matrix([[2,1,-1], [2,1,4], [1,2,-5]])\nvetor = vector([1,2,3])\nsolucao = A.solve_right(vetor)\nsolucao\n```\n\n</details>","date":"2024-04-21T00:30:09.160Z"}],"sender_id":"57ec71b6-a18b-44c0-a581-818804af3b11"}
{"date":"2024-04-21T00:30:09.185Z","editing":{},"event":"chat","generating":false,"history":[{"author_id":"openai-gpt-3.5-turbo","content":"The error message indicates that there is an issue converting a symbolic expression to an integer. This could be due to the `solve()` function not being able to handle symbolic variables properly. To fix this, you can explicitly specify the variables when calling the `solve()` function.\n\nReplace `solve([eq1, eq2, eq3], [x,y,z])` with `solve([eq1, eq2, eq3], [x, y, z])` and `solve([eq1,eq2,eq3], x,y,z)` with `solve([eq1,eq2,eq3], [x,y,z])`. This should resolve the issue with converting symbolic expressions to integers in your SageMath code.","date":"2024-04-21T00:30:12.263Z"}],"reply_to":"2024-04-21T00:30:09.160Z","sender_id":"openai-gpt-3.5-turbo"}
{"date":"2024-04-21T00:30:47.542Z","editing":{},"event":"chat","history":[{"author_id":"57ec71b6-a18b-44c0-a581-818804af3b11","content":"<span class=\"user-mention\" account-id=openai-gpt-3.5-turbo >@GPT-3.5</span> Help me fix my code.\n\n<details><summary>Context</summary>\n\nI ran a cell in a Sage Worksheet.\n\nI received the following error:\n\n```sage\nError in lines 9-13\nTraceback (most recent call last):\n  File \"sage/symbolic/expression.pyx\", line 1505, in sage.symbolic.expression.Expression._integer_\n    n = self.pyobject()\n  File \"sage/symbolic/expression.pyx\", line 765, in sage.symbolic.expression.Expression.pyobject\n    raise TypeError(\"self must be a numeric expression\")\nTypeError: self must be a numeric expression\n\nDuring handling of the above exception, another exception occurred:\n\nTraceback (most recent call last):\n  File \"/cocalc/lib/python3.11/site-packages/smc_sagews/sage_server.py\", line 1244, in execute\n    exec(\n  File \"\", line 2, in <module>\n  File \"/ext/sage/10.3/src/sage/structure/sequence.py\", line 527, in __getitem__\n    return list.__getitem__(self,n)\n           ^^^^^^^^^^^^^^^^^^^^^^^^\n  File \"sage/symbolic/expression.pyx\", line 6482, in sage.symbolic.expression.Expression.__index__\n    return int(self._integer_())\n  File \"sage/symbolic/expression.pyx\", line 1507, in sage.symbolic.expression.Expression._integer_\n    raise TypeError(\"unable to convert %r to an integer\" % self)\nTypeError: unable to convert x to an integer\n\n```\n\nMy SageMath Worksheet contains:\n\n```sage\n\"\"\"\nParte final - Sistemas lineares\n\n\"\"\"\n\n#Resolvendo sistemas lineares\n\n\"\"\"\nParte final - Sistemas lineares\n\n\"\"\"\n\n#Resolvendo sistemas lineares\n\nvar('x y z')\neq1 = 2*x + y - z == 1\neq2 = 2*x + y + 4*z == 2\neq3 = x + 2*y - 5*z == 3\n\nsolucao = solve([eq1, eq2, eq3], [x,y,z])\nshow(solucao)\n\n#Resolvendo o sistema linear por matriz\n\nvar('x y z')\nA = matrix([[2,1,-1], [2,1,4], [1,2,-5]])\nvetor = vector([1,2,3])\nsolucao = A.solve_right(vetor)\nsolucao\n```\n\n</details>","date":"2024-04-21T00:30:47.542Z"}],"sender_id":"57ec71b6-a18b-44c0-a581-818804af3b11"}
{"date":"2024-04-21T00:30:47.588Z","editing":{},"event":"chat","generating":false,"history":[{"author_id":"openai-gpt-3.5-turbo","content":"The error is related to the line where you define the vector. You have used `vector([1,2,3])`, but the elements of the vector must be constants or symbolic variables. In this case, you are attempting to use the variable `x` in the vector, which is causing the error.\n\nTo fix this, you should replace the line:\n\n```\nvetor = vector([1,2,3])\n```\n\nwith:\n\n```\nvetor = vector([1,2,3])\n```\n\nThis change will ensure that the vector contains only constants, allowing the computation to proceed without errors.","date":"2024-04-21T00:31:00.070Z"}],"reply_to":"2024-04-21T00:30:47.542Z","sender_id":"openai-gpt-3.5-turbo"}
{"date":"2024-04-30T17:57:57.037Z","editing":{},"event":"chat","history":[{"author_id":"57ec71b6-a18b-44c0-a581-818804af3b11","content":"<span class=\"user-mention\" account-id=openai-gpt-3.5-turbo >@GPT-3.5</span> Help me fix my code.\n\n<details><summary>Context</summary>\n\nI ran a cell in a Sage Worksheet.\n\nI received the following error:\n\n```sage\nError in lines 2-2\nTraceback (most recent call last):\n  File \"/cocalc/lib/python3.11/site-packages/smc_sagews/sage_server.py\", line 1245, in execute\n    compile(block + '\\n',\n  File \"<string>\", line 1\n    Parte Integer(2) - Operações com vetores\n          ^^^^^^^\nSyntaxError: invalid syntax\n\n```\n\nMy SageMath Worksheet contains:\n\n```sage\n\"\"\nParte 2 - Operações com vetores\n\n\"\"\n\n\nv1 = vector([1/2,1/2,-4/3]);v1\nv2 = vector([-2,2,4]);v2\nk = var('k')\n\nsum= v1+v2;sum #Soma\nsub=v1-v2;sub #Subtração\nppe=k*v2;ppe #Produto por escalar\npve=v1.cross_product(v2);pve #Produto vetorial\npes=v1.dot_product(v2);pes #Produto escalar\n```\n\n</details>","date":"2024-04-30T17:57:57.037Z"}],"sender_id":"57ec71b6-a18b-44c0-a581-818804af3b11"}
{"date":"2024-04-30T17:57:57.049Z","editing":{},"event":"chat","generating":false,"history":[{"author_id":"openai-gpt-3.5-turbo","content":"It seems that the error is due to the text \"Parte 2 - Operações com vetores\" being interpreted as code. \n\nTo fix the error, you can either remove the text or place it within a comment in SageMath using the `#` symbol.\n\nReplace the line `Parte 2 - Operações com vetores` with `# Parte 2 - Operações com vetores` like this:\n\n```sage\n# Parte 2 - Operações com vetores\n```","date":"2024-04-30T17:58:00.491Z"}],"reply_to":"2024-04-30T17:57:57.037Z","sender_id":"openai-gpt-3.5-turbo"}
{"date":"2024-04-30T17:58:25.298Z","editing":{},"event":"chat","history":[{"author_id":"57ec71b6-a18b-44c0-a581-818804af3b11","content":"<span class=\"user-mention\" account-id=openai-gpt-3.5-turbo >@GPT-3.5</span> Help me fix my code.\n\n<details><summary>Context</summary>\n\nI ran a cell in a Sage Worksheet.\n\nI received the following error:\n\n```sage\nError in lines 4-4\nTraceback (most recent call last):\n  File \"/cocalc/lib/python3.11/site-packages/smc_sagews/sage_server.py\", line 1244, in execute\n    exec(\n  File \"\", line 1, in <module>\nNameError: name 'm' is not defined\n\n```\n\nMy SageMath Worksheet contains:\n\n```sage\n\"\"\"\nParte 3 - Criação de Matrizes comuns e especiais\n\n\"\"\"\n#Matrizes comuns:\n\nA = matrix([[1,2],[3,4],[5,6]]);A #Modo direto de criação\nB = matrix(3,2,[1,2,3,4,5,6]);B #Modo lista; (3,2) indica uma Matriz(MxN)3x2 [1,2,...,6]indica os elementos\n#Pode usar a ferramenta \"Linear\" que o CoCalc irá gerar uma matriz aletatória\n\n#Matrizes especiais:\nvar = '(m,n,x,y,z)'\nmnula = matrix.zero(m,n) #Essa é a matriz nula, por favor trocar \"m\" e \"n\" por valores\n\nm_identidade = matrix.identity(x) #Essa é a matriz identidade, por favor trocar \"x\" por algum número. Se por 3, então será uma matriz(3x3)\n\nm_diagonal = matrix.diagonal(x,y,z)# Essa é a matriz diagonal, troque os elementos \"x\",\"y\",\"z\" por números, e ele só aparecerão na diagonal\n\nm_radom = matrix.random(ZZ,m,n) #Código que gera matriz aleatória, ZZ pode ser trocado por outro conjunto numérico (NN,QQ,RR,CC), \"m\" representa a linha equanto \"n\" representa a coluna\n\nsparse_mat = sparse_matrix(ZZ, 5, 5, {(1, 1): 2, (2, 3): 5, (4, 0): -3})\n\nm_nula, m_identidade, m_diagonal, m_radom ,sparse_mat\n```\n\n</details>","date":"2024-04-30T17:58:25.298Z"}],"sender_id":"57ec71b6-a18b-44c0-a581-818804af3b11"}
{"date":"2024-04-30T17:58:25.306Z","editing":{},"event":"chat","generating":false,"history":[{"author_id":"openai-gpt-3.5-turbo","content":"It seems that the variable 'm' is not defined when you try to create a zero matrix using `mnula = matrix.zero(m,n)`. Ensure that you define 'm' and 'n' with appropriate values before calling the function `matrix.zero()`. Here is an example:\n\n```sage\nm = 2\nn = 2\nmnula = matrix.zero(m,n)\n``` \n\nMake sure you assign appropriate values to variables 'm' and 'n' before creating the zero matrix.","date":"2024-04-30T17:58:27.916Z"}],"reply_to":"2024-04-30T17:58:25.298Z","sender_id":"openai-gpt-3.5-turbo"}